Workbook

Sheet E-impôts
A1: NCC | B1: Nom | C1: Portefeuille | D1: Adhesion | E1: N° Adhésion | F1: Adresse | G1: Regime | H1: Forme juridique | I1: Dirigeant | J1: =I268 -> 0 | K1: N°RCCM | L1: Centre d'impôts | M1: section | N1: parcelle | O1: codeacti | P1: montcapit
A2: 1850348X | B2: 5 PAINS ET 2 POISSONS | C2: =VLOOKUP(A2,Feuil2!$A$1:$AA$298,4,0) -> CABINET CFA | D2: 44224 | E2: =VLOOKUP('E-impôts'!A2,Feuil2!$A$1:$AA$298,8,0) -> DCK-CGA2021-Q165 | F2: =VLOOKUP('E-impôts'!A2,Feuil2!$A$1:$AA$298,24,0) -> COCODY CENTRE FACE INADES | G2: =VLOOKUP('E-impôts'!A2,Feuil2!$A$1:$AA$298,11,0) -> TEE | H2: =VLOOKUP('E-impôts'!A2,Feuil2!$A$1:$AA$298,10,0) -> SARL | I2: =VLOOKUP('E-impôts'!A2,Feuil2!$A$1:$AA$298,5,0) -> NULL | J2: =VLOOKUP('E-impôts'!A2,Feuil2!$A$1:$AA$298,19,0) -> 708047428 | K2: =VLOOKUP('E-impôts'!A2,Feuil2!$A$1:$AA$298,9,0) -> NULL | L2: =VLOOKUP('E-impôts'!A2,Feuil2!$A$1:$AA$298,15,0) -> Cocody | M2: =VLOOKUP('E-impôts'!A2,Feuil2!$A$1:$AA$298,13,0) -> NULL | N2: =VLOOKUP('E-impôts'!A2,Feuil2!$A$1:$AA$298,14,0) -> NULL | O2: =VLOOKUP('E-impôts'!A2,Feuil2!$A$1:$AA$298,16,0) -> NULL | P2: =VLOOKUP(A2,Feuil2!$A$1:$AA$298,17,0) -> NULL
A3: 2304047J | B3: 2TK & ASSOCIES | C3: =VLOOKUP(A3,Feuil2!$A$1:$AA$298,4,0) -> #N/A | D3: 45322 | E3: =VLOOKUP('E-impôts'!A3,Feuil2!$A$1:$AA$298,8,0) -> DCK-CGA2024-A062 | F3: =VLOOKUP('E-impôts'!A3,Feuil2!$A$1:$AA$298,24,0) -> COCODY AKOUEDO, LAURIER 15 | G3: =VLOOKUP('E-impôts'!A3,Feuil2!$A$1:$AA$298,11,0) -> TEE | H3: =VLOOKUP('E-impôts'!A3,Feuil2!$A$1:$AA$298,10,0) -> SARL | I3: =VLOOKUP('E-impôts'!A3,Feuil2!$A$1:$AA$298,5,0) -> M. KOFFI N'ZI BILE MARIUS | J3: =VLOOKUP('E-impôts'!A3,Feuil2!$A$1:$AA$298,19,0) -> 0708889604 /0707038895 | K3: =VLOOKUP('E-impôts'!A3,Feuil2!$A$1:$AA$298,9,0) -> CI-ABJ-03-2023-B12-05066 | L3: =VLOOKUP('E-impôts'!A3,Feuil2!$A$1:$AA$298,15,0) -> Riviera II | M3: =VLOOKUP('E-impôts'!A3,Feuil2!$A$1:$AA$298,13,0) -> N/D | N3: =VLOOKUP('E-impôts'!A3,Feuil2!$A$1:$AA$298,14,0) -> N/D | O3: =VLOOKUP('E-impôts'!A3,Feuil2!$A$1:$AA$298,16,0) -> SCE0306 | P3: =VLOOKUP(A3,Feuil2!$A$1:$AA$298,17,0) -> 1000000
A4: 2037325R | B4: 2N IMMOBILIER | C4: =VLOOKUP(A4,Feuil2!$A$1:$AA$298,4,0) -> CABINET CFA | D4: 44224 | E4: =VLOOKUP('E-impôts'!A4,Feuil2!$A$1:$AA$298,8,0) -> DCK-CGA2019-A006 | F4: =VLOOKUP('E-impôts'!A4,Feuil2!$A$1:$AA$298,24,0) -> DEUX PLATEAUX SICOGI | G4: =VLOOKUP('E-impôts'!A4,Feuil2!$A$1:$AA$298,11,0) -> TEE | H4: =VLOOKUP('E-impôts'!A4,Feuil2!$A$1:$AA$298,10,0) -> SARL | I4: =VLOOKUP('E-impôts'!A4,Feuil2!$A$1:$AA$298,5,0) -> NULL | J4: =VLOOKUP('E-impôts'!A4,Feuil2!$A$1:$AA$298,19,0) -> 708514241 | K4: =VLOOKUP('E-impôts'!A4,Feuil2!$A$1:$AA$298,9,0) -> NULL | L4: =VLOOKUP('E-impôts'!A4,Feuil2!$A$1:$AA$298,15,0) -> II Plateaux I | M4: =VLOOKUP('E-impôts'!A4,Feuil2!$A$1:$AA$298,13,0) -> NULL | N4: =VLOOKUP('E-impôts'!A4,Feuil2!$A$1:$AA$298,14,0) -> NULL | O4: =VLOOKUP('E-impôts'!A4,Feuil2!$A$1:$AA$298,16,0) -> NULL | P4: =VLOOKUP(A4,Feuil2!$A$1:$AA$298,17,0) -> NULL
A5: 2244766Y | B5: ZOUE SEA ESTELLE | C5: =VLOOKUP(A5,Feuil2!$A$1:$AA$298,4,0) -> #N/A | D5: 45321 | E5: =VLOOKUP('E-impôts'!A5,Feuil2!$A$1:$AA$298,8,0) -> DCK-CGA2024-A088 | F5: =VLOOKUP('E-impôts'!A5,Feuil2!$A$1:$AA$298,24,0) -> COCODY RIVIERA AKOUEDO EXT | G5: =VLOOKUP('E-impôts'!A5,Feuil2!$A$1:$AA$298,11,0) -> TEE | H5: =VLOOKUP('E-impôts'!A5,Feuil2!$A$1:$AA$298,10,0) -> ENTREPRISE INDIVIDUELLE | I5: =VLOOKUP('E-impôts'!A5,Feuil2!$A$1:$AA$298,5,0) -> ZOUE SEA ESTELLE | J5: =VLOOKUP('E-impôts'!A5,Feuil2!$A$1:$AA$298,19,0) -> 505954425 | K5: =VLOOKUP('E-impôts'!A5,Feuil2!$A$1:$AA$298,9,0) -> CI-ABJ-032022-A10-04009 | L5: =VLOOKUP('E-impôts'!A5,Feuil2!$A$1:$AA$298,15,0) -> Cocody | M5: =VLOOKUP('E-impôts'!A5,Feuil2!$A$1:$AA$298,13,0) -> 0 | N5: =VLOOKUP('E-impôts'!A5,Feuil2!$A$1:$AA$298,14,0) -> 0 | O5: I550000 | P5: =VLOOKUP(A5,Feuil2!$A$1:$AA$298,17,0) -> 25000
A6: 1507261D | B6: ZANGRE HAROUNA | C6: =VLOOKUP('E-impôts'!A6,Feuil2!$A$1:$AA$298,4,0) -> DCK | D6: 43479 | E6: =VLOOKUP('E-impôts'!A6,Feuil2!$A$1:$AA$298,8,0) -> DCK-CGA2019-A024 | F6: =VLOOKUP('E-impôts'!A6,Feuil2!$A$1:$AA$298,24,0) -> COCODY SAINT JEAN | G6: =VLOOKUP('E-impôts'!A6,Feuil2!$A$1:$AA$298,11,0) -> TEE | H6: =VLOOKUP('E-impôts'!A6,Feuil2!$A$1:$AA$298,10,0) -> ENTREPRISE INDIVIDUELLE | I6: ZANGRE HAROUNA | J6: =VLOOKUP('E-impôts'!A6,Feuil2!$A$1:$AA$298,19,0) -> 505843545 | K6: =VLOOKUP('E-impôts'!A6,Feuil2!$A$1:$AA$298,9,0) -> NULL | L6: =VLOOKUP('E-impôts'!A6,Feuil2!$A$1:$AA$298,15,0) -> Cocody | M6: =VLOOKUP('E-impôts'!A6,Feuil2!$A$1:$AA$298,13,0) -> NULL | N6: =VLOOKUP('E-impôts'!A6,Feuil2!$A$1:$AA$298,14,0) -> NULL | O6: G470306 | P6: =VLOOKUP(A6,Feuil2!$A$1:$AA$298,17,0) -> NULL
A7: 0514603E | B7: ZALLE MAHAMOUD | C7: =VLOOKUP('E-impôts'!A7,Feuil2!$A$1:$AA$298,4,0) -> DCK | D7: 43479 | E7: =VLOOKUP('E-impôts'!A7,Feuil2!$A$1:$AA$298,8,0) -> DCK-CGA2019-A025 | F7: =VLOOKUP('E-impôts'!A7,Feuil2!$A$1:$AA$298,24,0) -> COCODY ANGRE-DJIBI | G7: =VLOOKUP('E-impôts'!A7,Feuil2!$A$1:$AA$298,11,0) -> TEE | H7: =VLOOKUP('E-impôts'!A7,Feuil2!$A$1:$AA$298,10,0) -> ENTREPRISE INDIVIDUELLE | I7: =VLOOKUP('E-impôts'!A7,Feuil2!$A$1:$AA$298,5,0) -> ZALLE MAHAMOUD | J7: =VLOOKUP('E-impôts'!A7,Feuil2!$A$1:$AA$298,19,0) -> 505938989 | K7: =VLOOKUP('E-impôts'!A7,Feuil2!$A$1:$AA$298,9,0) -> CI-ABJ-2011-A-6598 | L7: =VLOOKUP('E-impôts'!A7,Feuil2!$A$1:$AA$298,15,0) -> II Plateaux Djibi | M7: =VLOOKUP('E-impôts'!A7,Feuil2!$A$1:$AA$298,13,0) -> N/D | N7: =VLOOKUP('E-impôts'!A7,Feuil2!$A$1:$AA$298,14,0) -> N/D | O7: G470205 | P7: =VLOOKUP(A7,Feuil2!$A$1:$AA$298,17,0) -> 0
A8: 1709117F | B8: YONH LAINE THEOPHILE | C8: =VLOOKUP('E-impôts'!A8,Feuil2!$A$1:$AA$298,4,0) -> CABINET CFA | D8: 44224 | E8: =VLOOKUP('E-impôts'!A8,Feuil2!$A$1:$AA$298,8,0) -> DCK-CGA2021-Q144 | F8: =VLOOKUP('E-impôts'!A8,Feuil2!$A$1:$AA$298,24,0) -> RIVIERA BONOUMIN | G8: =VLOOKUP('E-impôts'!A8,Feuil2!$A$1:$AA$298,11,0) -> TEE | H8: =VLOOKUP('E-impôts'!A8,Feuil2!$A$1:$AA$298,10,0) -> ENTREPRISE INDIVIDUELLE | I8: =VLOOKUP('E-impôts'!A8,Feuil2!$A$1:$AA$298,5,0) -> NULL | J8: =VLOOKUP('E-impôts'!A8,Feuil2!$A$1:$AA$298,19,0) -> 757740578 | K8: =VLOOKUP('E-impôts'!A8,Feuil2!$A$1:$AA$298,9,0) -> NULL | L8: =VLOOKUP('E-impôts'!A8,Feuil2!$A$1:$AA$298,15,0) -> II Plateaux I | M8: =VLOOKUP('E-impôts'!A8,Feuil2!$A$1:$AA$298,13,0) -> NULL | N8: =VLOOKUP('E-impôts'!A8,Feuil2!$A$1:$AA$298,14,0) -> NULL | O8: =VLOOKUP('E-impôts'!A8,Feuil2!$A$1:$AA$298,16,0) -> NULL | P8: =VLOOKUP(A8,Feuil2!$A$1:$AA$298,17,0) -> NULL
A9: 0709432N | B9: YIRA SIAKA | C9: =VLOOKUP('E-impôts'!A9,Feuil2!$A$1:$AA$298,4,0) -> DCK | D9: 43479 | E9: =VLOOKUP('E-impôts'!A9,Feuil2!$A$1:$AA$298,8,0) -> DCK-CGA2019-A005 | F9: =VLOOKUP('E-impôts'!A9,Feuil2!$A$1:$AA$298,24,0) -> COCODY RIVIERA BONOUMIN | G9: =VLOOKUP('E-impôts'!A9,Feuil2!$A$1:$AA$298,11,0) -> TEE | H9: =VLOOKUP('E-impôts'!A9,Feuil2!$A$1:$AA$298,10,0) -> ENTREPRISE INDIVIDUELLE | I9: =VLOOKUP('E-impôts'!A9,Feuil2!$A$1:$AA$298,5,0) -> YIRA SIAKA | J9: =VLOOKUP('E-impôts'!A9,Feuil2!$A$1:$AA$298,19,0) -> 757740598 | K9: =VLOOKUP('E-impôts'!A9,Feuil2!$A$1:$AA$298,9,0) -> 09 BP 2525 ABIDJAN 09 | L9: =VLOOKUP('E-impôts'!A9,Feuil2!$A$1:$AA$298,15,0) -> II Plateaux III | M9: =VLOOKUP('E-impôts'!A9,Feuil2!$A$1:$AA$298,13,0) -> N/D | N9: =VLOOKUP('E-impôts'!A9,Feuil2!$A$1:$AA$298,14,0) -> N/D | O9: H490202 | P9: =VLOOKUP(A9,Feuil2!$A$1:$AA$298,17,0) -> 6000000
A10: 9410895U | B10: YERE LOU EPSE YACE Nenenan Blandine | C10: =VLOOKUP('E-impôts'!A10,Feuil2!$A$1:$AA$298,4,0) -> DCK | D10: 43479 | E10: =VLOOKUP('E-impôts'!A10,Feuil2!$A$1:$AA$298,8,0) -> DCK-CGA2019-A040 | F10: =VLOOKUP('E-impôts'!A10,Feuil2!$A$1:$AA$298,24,0) -> COCODY II PLATEAUX VALLON | G10: =VLOOKUP('E-impôts'!A10,Feuil2!$A$1:$AA$298,11,0) -> TEE | H10: =VLOOKUP('E-impôts'!A10,Feuil2!$A$1:$AA$298,10,0) -> ENTREPRISE INDIVIDUELLE | I10: YERE LOU EPSE YACE Nenenan Blandine | J10: =VLOOKUP('E-impôts'!A10,Feuil2!$A$1:$AA$298,19,0) -> 707070392 | K10: =VLOOKUP('E-impôts'!A10,Feuil2!$A$1:$AA$298,9,0) -> NULL | L10: =VLOOKUP('E-impôts'!A10,Feuil2!$A$1:$AA$298,15,0) -> II Plateaux II | M10: =VLOOKUP('E-impôts'!A10,Feuil2!$A$1:$AA$298,13,0) -> NULL | N10: =VLOOKUP('E-impôts'!A10,Feuil2!$A$1:$AA$298,14,0) -> NULL | O10: G4702 | P10: =VLOOKUP(A10,Feuil2!$A$1:$AA$298,17,0) -> NULL
A11: 0800398U | B11: YEBOUE EPSE BOUAH ADJOUA IRENE | C11: =VLOOKUP('E-impôts'!A11,Feuil2!$A$1:$AA$298,4,0) -> #N/A | D11: 43479 | E11: =VLOOKUP('E-impôts'!A11,Feuil2!$A$1:$AA$298,8,0) -> #N/A | F11: =VLOOKUP('E-impôts'!A11,Feuil2!$A$1:$AA$298,24,0) -> #N/A | G11: =VLOOKUP('E-impôts'!A11,Feuil2!$A$1:$AA$298,11,0) -> #N/A | H11: =VLOOKUP('E-impôts'!A11,Feuil2!$A$1:$AA$298,10,0) -> #N/A | I11: =VLOOKUP('E-impôts'!A11,Feuil2!$A$1:$AA$298,5,0) -> #N/A | J11: =VLOOKUP('E-impôts'!A11,Feuil2!$A$1:$AA$298,19,0) -> #N/A | K11: =VLOOKUP('E-impôts'!A11,Feuil2!$A$1:$AA$298,9,0) -> #N/A | L11: =VLOOKUP('E-impôts'!A11,Feuil2!$A$1:$AA$298,15,0) -> #N/A | M11: =VLOOKUP('E-impôts'!A11,Feuil2!$A$1:$AA$298,13,0) -> #N/A | N11: =VLOOKUP('E-impôts'!A11,Feuil2!$A$1:$AA$298,14,0) -> #N/A | O11: =VLOOKUP('E-impôts'!A11,Feuil2!$A$1:$AA$298,16,0) -> #N/A | P11: =VLOOKUP(A11,Feuil2!$A$1:$AA$298,17,0) -> #N/A
A12: 1865233X | B12: YAPO YAPO GHISLAIN CYRILLE | C12: =VLOOKUP('E-impôts'!A12,Feuil2!$A$1:$AA$298,4,0) -> DCK | D12: 44574 | E12: =VLOOKUP('E-impôts'!A12,Feuil2!$A$1:$AA$298,8,0) -> DCK-CGA-2022-J004 | F12: =VLOOKUP('E-impôts'!A12,Feuil2!$A$1:$AA$298,24,0) -> COCODY RIVIERA II | G12: =VLOOKUP('E-impôts'!A12,Feuil2!$A$1:$AA$298,11,0) -> TEE | H12: =VLOOKUP('E-impôts'!A12,Feuil2!$A$1:$AA$298,10,0) -> ENTREPRISE INDIVIDUELLE | I12: =VLOOKUP('E-impôts'!A12,Feuil2!$A$1:$AA$298,5,0) -> NULL | J12: =VLOOKUP('E-impôts'!A12,Feuil2!$A$1:$AA$298,19,0) -> 778120796 | K12: =VLOOKUP('E-impôts'!A12,Feuil2!$A$1:$AA$298,9,0) -> NULL | L12: =VLOOKUP('E-impôts'!A12,Feuil2!$A$1:$AA$298,15,0) -> Riviera I | M12: =VLOOKUP('E-impôts'!A12,Feuil2!$A$1:$AA$298,13,0) -> NULL | N12: =VLOOKUP('E-impôts'!A12,Feuil2!$A$1:$AA$298,14,0) -> NULL | O12: =VLOOKUP('E-impôts'!A12,Feuil2!$A$1:$AA$298,16,0) -> NULL | P12: =VLOOKUP(A12,Feuil2!$A$1:$AA$298,17,0) -> NULL
A13: 1345558K | B13: YAO N'GUESSAN ANGE-FABRICE | C13: =VLOOKUP('E-impôts'!A13,Feuil2!$A$1:$AA$298,4,0) -> CABINET CFA | D13: 44224 | E13: =VLOOKUP('E-impôts'!A13,Feuil2!$A$1:$AA$298,8,0) -> DCK-CGA2021-Q139 | F13: =VLOOKUP('E-impôts'!A13,Feuil2!$A$1:$AA$298,24,0) -> 0 | G13: =VLOOKUP('E-impôts'!A13,Feuil2!$A$1:$AA$298,11,0) -> TEE | H13: =VLOOKUP('E-impôts'!A13,Feuil2!$A$1:$AA$298,10,0) -> ENTREPRISE INDIVIDUELLE | I13: =VLOOKUP('E-impôts'!A13,Feuil2!$A$1:$AA$298,5,0) -> NULL | J13: =VLOOKUP('E-impôts'!A13,Feuil2!$A$1:$AA$298,19,0) -> 0 | K13: =VLOOKUP('E-impôts'!A13,Feuil2!$A$1:$AA$298,9,0) -> NULL | L13: =VLOOKUP('E-impôts'!A13,Feuil2!$A$1:$AA$298,15,0) -> II Plateaux I | M13: =VLOOKUP('E-impôts'!A13,Feuil2!$A$1:$AA$298,13,0) -> NULL | N13: =VLOOKUP('E-impôts'!A13,Feuil2!$A$1:$AA$298,14,0) -> NULL | O13: =VLOOKUP('E-impôts'!A13,Feuil2!$A$1:$AA$298,16,0) -> NULL | P13: =VLOOKUP(A13,Feuil2!$A$1:$AA$298,17,0) -> NULL
A14: 1212885P | B14: YAO N'Guessan Adele Epse Djedje | C14: =VLOOKUP('E-impôts'!A14,Feuil2!$A$1:$AA$298,4,0) -> DCK | D14: 43479 | E14: =VLOOKUP('E-impôts'!A14,Feuil2!$A$1:$AA$298,8,0) -> DCK-CGA2019-A027 | F14: =VLOOKUP('E-impôts'!A14,Feuil2!$A$1:$AA$298,24,0) -> RIVIERA BONOUMIN | G14: =VLOOKUP('E-impôts'!A14,Feuil2!$A$1:$AA$298,11,0) -> TEE | H14: =VLOOKUP('E-impôts'!A14,Feuil2!$A$1:$AA$298,10,0) -> ENTREPRISE INDIVIDUELLE | I14: =VLOOKUP('E-impôts'!A14,Feuil2!$A$1:$AA$298,5,0) -> YOA N'GUESSAN ADELE EPSE DJEDJE | J14: =VLOOKUP('E-impôts'!A14,Feuil2!$A$1:$AA$298,19,0) -> 505060740 | K14: =VLOOKUP('E-impôts'!A14,Feuil2!$A$1:$AA$298,9,0) -> CI-ABJ-2012-A-1024 | L14: =VLOOKUP('E-impôts'!A14,Feuil2!$A$1:$AA$298,15,0) -> II Plateaux III | M14: =VLOOKUP('E-impôts'!A14,Feuil2!$A$1:$AA$298,13,0) -> ABC | N14: =VLOOKUP('E-impôts'!A14,Feuil2!$A$1:$AA$298,14,0) -> 39 | O14: G470201 | P14: =VLOOKUP(A14,Feuil2!$A$1:$AA$298,17,0) -> 0
A15: 1900445C | B15: YAO N'DRI FRANCK AIME | C15: =VLOOKUP('E-impôts'!A15,Feuil2!$A$1:$AA$298,4,0) -> DCK | D15: 43847 | E15: =VLOOKUP('E-impôts'!A15,Feuil2!$A$1:$AA$298,8,0) -> DCK-CGA2020-A051 | F15: =VLOOKUP('E-impôts'!A15,Feuil2!$A$1:$AA$298,24,0) -> COCODY BONOUMIN | G15: =VLOOKUP('E-impôts'!A15,Feuil2!$A$1:$AA$298,11,0) -> TEE | H15: =VLOOKUP('E-impôts'!A15,Feuil2!$A$1:$AA$298,10,0) -> ENTREPRISE INDIVIDUELLE | I15: =VLOOKUP('E-impôts'!A15,Feuil2!$A$1:$AA$298,5,0) -> YAO N'DRI FRANCK AIME | J15: =VLOOKUP('E-impôts'!A15,Feuil2!$A$1:$AA$298,19,0) -> 708112943 | K15: =VLOOKUP('E-impôts'!A15,Feuil2!$A$1:$AA$298,9,0) -> 0 | L15: =VLOOKUP('E-impôts'!A15,Feuil2!$A$1:$AA$298,15,0) -> II Plateaux III | M15: =VLOOKUP('E-impôts'!A15,Feuil2!$A$1:$AA$298,13,0) -> ABH | N15: =VLOOKUP('E-impôts'!A15,Feuil2!$A$1:$AA$298,14,0) -> 10 | O15: Q860100 | P15: =VLOOKUP(A15,Feuil2!$A$1:$AA$298,17,0) -> 0
A16: 2242835K | B16: YANKAN-MO | C16: =VLOOKUP('E-impôts'!A16,Feuil2!$A$1:$AA$298,4,0) -> GOHI | D16: 44951 | E16: =VLOOKUP('E-impôts'!A16,Feuil2!$A$1:$AA$298,8,0) -> DCK-CGA2023-J018 | F16: =VLOOKUP('E-impôts'!A16,Feuil2!$A$1:$AA$298,24,0) -> COCODY ANGRE 7E TRANCHE OSCARS | G16: =VLOOKUP('E-impôts'!A16,Feuil2!$A$1:$AA$298,11,0) -> TEE | H16: =VLOOKUP('E-impôts'!A16,Feuil2!$A$1:$AA$298,10,0) -> SARL | I16: =VLOOKUP('E-impôts'!A16,Feuil2!$A$1:$AA$298,5,0) -> NULL | J16: =VLOOKUP('E-impôts'!A16,Feuil2!$A$1:$AA$298,19,0) -> 757118226 | K16: =VLOOKUP('E-impôts'!A16,Feuil2!$A$1:$AA$298,9,0) -> NULL | L16: =VLOOKUP('E-impôts'!A16,Feuil2!$A$1:$AA$298,15,0) -> II Plateaux I | M16: =VLOOKUP('E-impôts'!A16,Feuil2!$A$1:$AA$298,13,0) -> NULL | N16: =VLOOKUP('E-impôts'!A16,Feuil2!$A$1:$AA$298,14,0) -> NULL | O16: =VLOOKUP('E-impôts'!A16,Feuil2!$A$1:$AA$298,16,0) -> NULL | P16: =VLOOKUP(A16,Feuil2!$A$1:$AA$298,17,0) -> NULL
A17: 1800364N | B17: YAKIME DESIGN | C17: =VLOOKUP('E-impôts'!A17,Feuil2!$A$1:$AA$298,4,0) -> #N/A | D17: 43845 | E17: =VLOOKUP('E-impôts'!A17,Feuil2!$A$1:$AA$298,8,0) -> #N/A | F17: =VLOOKUP('E-impôts'!A17,Feuil2!$A$1:$AA$298,24,0) -> #N/A | G17: =VLOOKUP('E-impôts'!A17,Feuil2!$A$1:$AA$298,11,0) -> #N/A | H17: =VLOOKUP('E-impôts'!A17,Feuil2!$A$1:$AA$298,10,0) -> #N/A | I17: TOURE EPSE M'BAYE MARIAM | J17: =VLOOKUP('E-impôts'!A17,Feuil2!$A$1:$AA$298,19,0) -> #N/A | K17: =VLOOKUP('E-impôts'!A17,Feuil2!$A$1:$AA$298,9,0) -> #N/A | L17: =VLOOKUP('E-impôts'!A17,Feuil2!$A$1:$AA$298,15,0) -> #N/A | M17: =VLOOKUP('E-impôts'!A17,Feuil2!$A$1:$AA$298,13,0) -> #N/A | N17: =VLOOKUP('E-impôts'!A17,Feuil2!$A$1:$AA$298,14,0) -> #N/A | O17: N810001 | P17: =VLOOKUP(A17,Feuil2!$A$1:$AA$298,17,0) -> #N/A
A18: 1827528R | B18: YAGUERA & COMPAGNIE | C18: =VLOOKUP('E-impôts'!A18,Feuil2!$A$1:$AA$298,4,0) -> DCK | D18: 43479 | E18: =VLOOKUP('E-impôts'!A18,Feuil2!$A$1:$AA$298,8,0) -> DCK-CGA2019-A007 | F18: =VLOOKUP('E-impôts'!A18,Feuil2!$A$1:$AA$298,24,0) -> COCODY ANGRE 7E TRANCHE | G18: =VLOOKUP('E-impôts'!A18,Feuil2!$A$1:$AA$298,11,0) -> TEE | H18: =VLOOKUP('E-impôts'!A18,Feuil2!$A$1:$AA$298,10,0) -> SARL | I18: YACE EPSE ANGUERA NINA CATHERINE | J18: =VLOOKUP('E-impôts'!A18,Feuil2!$A$1:$AA$298,19,0) -> 789844008 | K18: =VLOOKUP('E-impôts'!A18,Feuil2!$A$1:$AA$298,9,0) -> NULL | L18: =VLOOKUP('E-impôts'!A18,Feuil2!$A$1:$AA$298,15,0) -> II Plateaux I | M18: =VLOOKUP('E-impôts'!A18,Feuil2!$A$1:$AA$298,13,0) -> NULL | N18: =VLOOKUP('E-impôts'!A18,Feuil2!$A$1:$AA$298,14,0) -> NULL | O18: L680100 | P18: =VLOOKUP(A18,Feuil2!$A$1:$AA$298,17,0) -> NULL
A19: 0714977C | B19: YACE EMMANUELLE | C19: =VLOOKUP('E-impôts'!A19,Feuil2!$A$1:$AA$298,4,0) -> DCK | D19: 43479 | E19: =VLOOKUP('E-impôts'!A19,Feuil2!$A$1:$AA$298,8,0) -> DCK-CGA2019-A014 | F19: =VLOOKUP('E-impôts'!A19,Feuil2!$A$1:$AA$298,24,0) -> COCODY ANGRE 7E TRANCHE | G19: =VLOOKUP('E-impôts'!A19,Feuil2!$A$1:$AA$298,11,0) -> TEE | H19: =VLOOKUP('E-impôts'!A19,Feuil2!$A$1:$AA$298,10,0) -> ENTREPRISE INDIVIDUELLE | I19: =VLOOKUP('E-impôts'!A19,Feuil2!$A$1:$AA$298,5,0) -> YACE EMMANUELLE | J19: =VLOOKUP('E-impôts'!A19,Feuil2!$A$1:$AA$298,19,0) -> 707070392 | K19: =VLOOKUP('E-impôts'!A19,Feuil2!$A$1:$AA$298,9,0) -> CI-ABJ-2014-A-1249 | L19: =VLOOKUP('E-impôts'!A19,Feuil2!$A$1:$AA$298,15,0) -> II Plateaux III | M19: =VLOOKUP('E-impôts'!A19,Feuil2!$A$1:$AA$298,13,0) -> OZ | N19: =VLOOKUP('E-impôts'!A19,Feuil2!$A$1:$AA$298,14,0) -> 207 | O19: L680100 | P19: =VLOOKUP(A19,Feuil2!$A$1:$AA$298,17,0) -> 0
A20: 2240985C | B20: X-YOLO | C20: =VLOOKUP('E-impôts'!A20,Feuil2!$A$1:$AA$298,4,0) -> #N/A | D20: 45316 | E20: =VLOOKUP('E-impôts'!A20,Feuil2!$A$1:$AA$298,8,0) -> DCK-CGA2024-A033 | F20: =VLOOKUP('E-impôts'!A20,Feuil2!$A$1:$AA$298,24,0) -> BINGERVILLE | G20: =VLOOKUP('E-impôts'!A20,Feuil2!$A$1:$AA$298,11,0) -> TEE | H20: =VLOOKUP('E-impôts'!A20,Feuil2!$A$1:$AA$298,10,0) -> SARL | I20: =VLOOKUP('E-impôts'!A20,Feuil2!$A$1:$AA$298,5,0) -> WANG JINGZHONG | J20: =VLOOKUP('E-impôts'!A20,Feuil2!$A$1:$AA$298,19,0) -> 768151168 | K20: =VLOOKUP('E-impôts'!A20,Feuil2!$A$1:$AA$298,9,0) -> CI-ABJ-03-2022-B13-03433 | L20: =VLOOKUP('E-impôts'!A20,Feuil2!$A$1:$AA$298,15,0) -> Bingerville | M20: =VLOOKUP('E-impôts'!A20,Feuil2!$A$1:$AA$298,13,0) -> 0 | N20: =VLOOKUP('E-impôts'!A20,Feuil2!$A$1:$AA$298,14,0) -> 0 | O20: =VLOOKUP('E-impôts'!A20,Feuil2!$A$1:$AA$298,16,0) -> 0 | P20: =VLOOKUP(A20,Feuil2!$A$1:$AA$298,17,0) -> 1000000
A21: 1709973R | B21: WILSEM CONSULTING | C21: =VLOOKUP('E-impôts'!A21,Feuil2!$A$1:$AA$298,4,0) -> #N/A | D21: 45322 | E21: =VLOOKUP('E-impôts'!A21,Feuil2!$A$1:$AA$298,8,0) -> DCK-CGA2024-A059 | F21: =VLOOKUP('E-impôts'!A21,Feuil2!$A$1:$AA$298,24,0) -> ABIDJAN COCODY ATTOBAN | G21: =VLOOKUP('E-impôts'!A21,Feuil2!$A$1:$AA$298,11,0) -> TEE | H21: =VLOOKUP('E-impôts'!A21,Feuil2!$A$1:$AA$298,10,0) -> SARL | I21: =VLOOKUP('E-impôts'!A21,Feuil2!$A$1:$AA$298,5,0) -> TONYI AMEGADJIN | J21: =VLOOKUP('E-impôts'!A21,Feuil2!$A$1:$AA$298,19,0) -> 05 45 83 24 70 / 07 48 71 99 0 | K21: =VLOOKUP('E-impôts'!A21,Feuil2!$A$1:$AA$298,9,0) -> CI-ABJ-2016-B-00665 | L21: =VLOOKUP('E-impôts'!A21,Feuil2!$A$1:$AA$298,15,0) -> II Plateaux III | M21: =VLOOKUP('E-impôts'!A21,Feuil2!$A$1:$AA$298,13,0) -> PW | N21: =VLOOKUP('E-impôts'!A21,Feuil2!$A$1:$AA$298,14,0) -> 1054 | O21: =VLOOKUP('E-impôts'!A21,Feuil2!$A$1:$AA$298,16,0) -> SCE0801 | P21: =VLOOKUP(A21,Feuil2!$A$1:$AA$298,17,0) -> 1.000.000
A22: 1849567E | B22: WEST AFRICA FOOD AS-AGRILAND | C22: =VLOOKUP('E-impôts'!A22,Feuil2!$A$1:$AA$298,4,0) -> CABINET CFA | D22: 44592 | E22: =VLOOKUP('E-impôts'!A22,Feuil2!$A$1:$AA$298,8,0) -> DCK-CGA2022-J036 | F22: =VLOOKUP('E-impôts'!A22,Feuil2!$A$1:$AA$298,24,0) -> COCODY II PLATEAUX 7E TRANCHE | G22: =VLOOKUP('E-impôts'!A22,Feuil2!$A$1:$AA$298,11,0) -> TEE | H22: =VLOOKUP('E-impôts'!A22,Feuil2!$A$1:$AA$298,10,0) -> SARL | I22: =VLOOKUP('E-impôts'!A22,Feuil2!$A$1:$AA$298,5,0) -> NULL | J22: =VLOOKUP('E-impôts'!A22,Feuil2!$A$1:$AA$298,19,0) -> 505423838 | K22: =VLOOKUP('E-impôts'!A22,Feuil2!$A$1:$AA$298,9,0) -> NULL | L22: =VLOOKUP('E-impôts'!A22,Feuil2!$A$1:$AA$298,15,0) -> II Plateaux I | M22: =VLOOKUP('E-impôts'!A22,Feuil2!$A$1:$AA$298,13,0) -> NULL | N22: =VLOOKUP('E-impôts'!A22,Feuil2!$A$1:$AA$298,14,0) -> NULL | O22: =VLOOKUP('E-impôts'!A22,Feuil2!$A$1:$AA$298,16,0) -> NULL | P22: =VLOOKUP(A22,Feuil2!$A$1:$AA$298,17,0) -> NULL
A23: 2300875R | B23: WELDING VISION COTE D'IVOIRE | C23: =VLOOKUP('E-impôts'!A23,Feuil2!$A$1:$AA$298,4,0) -> #N/A | D23: 45316 | E23: =VLOOKUP('E-impôts'!A23,Feuil2!$A$1:$AA$298,8,0) -> DCK-CGA2024-A031 | F23: =VLOOKUP('E-impôts'!A23,Feuil2!$A$1:$AA$298,24,0) -> COCODY ANGRE SOLEIL 3 | G23: =VLOOKUP('E-impôts'!A23,Feuil2!$A$1:$AA$298,11,0) -> TEE | H23: =VLOOKUP('E-impôts'!A23,Feuil2!$A$1:$AA$298,10,0) -> SARL | I23: =VLOOKUP('E-impôts'!A23,Feuil2!$A$1:$AA$298,5,0) -> EKUE ADADE | J23: =VLOOKUP('E-impôts'!A23,Feuil2!$A$1:$AA$298,19,0) -> 757263143 | K23: =VLOOKUP('E-impôts'!A23,Feuil2!$A$1:$AA$298,9,0) -> CI-ABJ-03-2023-B13-02205 | L23: =VLOOKUP('E-impôts'!A23,Feuil2!$A$1:$AA$298,15,0) -> II Plateaux Djibi | M23: =VLOOKUP('E-impôts'!A23,Feuil2!$A$1:$AA$298,13,0) -> 0 | N23: =VLOOKUP('E-impôts'!A23,Feuil2!$A$1:$AA$298,14,0) -> 0 | O23: =VLOOKUP('E-impôts'!A23,Feuil2!$A$1:$AA$298,16,0) -> 0 | P23: =VLOOKUP(A23,Feuil2!$A$1:$AA$298,17,0) -> 1000000
A24: 2242769N | B24: VK SERVICES PLUS | C24: =VLOOKUP('E-impôts'!A24,Feuil2!$A$1:$AA$298,4,0) -> CABINET CFA | D24: 44774 | E24: =VLOOKUP('E-impôts'!A24,Feuil2!$A$1:$AA$298,8,0) -> DCK-CGA2022-J077 | F24: =VLOOKUP('E-impôts'!A24,Feuil2!$A$1:$AA$298,24,0) -> COCODY ANGRE DJIBI | G24: =VLOOKUP('E-impôts'!A24,Feuil2!$A$1:$AA$298,11,0) -> TEE | H24: =VLOOKUP('E-impôts'!A24,Feuil2!$A$1:$AA$298,10,0) -> SARL | I24: =VLOOKUP('E-impôts'!A24,Feuil2!$A$1:$AA$298,5,0) -> NULL | J24: =VLOOKUP('E-impôts'!A24,Feuil2!$A$1:$AA$298,19,0) -> 757417993 | K24: =VLOOKUP('E-impôts'!A24,Feuil2!$A$1:$AA$298,9,0) -> NULL | L24: =VLOOKUP('E-impôts'!A24,Feuil2!$A$1:$AA$298,15,0) -> II Plateaux Djibi | M24: =VLOOKUP('E-impôts'!A24,Feuil2!$A$1:$AA$298,13,0) -> NULL | N24: =VLOOKUP('E-impôts'!A24,Feuil2!$A$1:$AA$298,14,0) -> NULL | O24: =VLOOKUP('E-impôts'!A24,Feuil2!$A$1:$AA$298,16,0) -> NULL | P24: =VLOOKUP(A24,Feuil2!$A$1:$AA$298,17,0) -> NULL
A25: 2243769Z | B25: VIDAS GROUP HOLDING | C25: =VLOOKUP('E-impôts'!A25,Feuil2!$A$1:$AA$298,4,0) -> DCK | D25: 44956 | E25: =VLOOKUP('E-impôts'!A25,Feuil2!$A$1:$AA$298,8,0) -> DCK-CGA-2022-J031 | F25: =VLOOKUP('E-impôts'!A25,Feuil2!$A$1:$AA$298,24,0) -> COCODY BONOUMIN | G25: =VLOOKUP('E-impôts'!A25,Feuil2!$A$1:$AA$298,11,0) -> TEE | H25: =VLOOKUP('E-impôts'!A25,Feuil2!$A$1:$AA$298,10,0) -> SARL | I25: =VLOOKUP('E-impôts'!A25,Feuil2!$A$1:$AA$298,5,0) -> DJOGBENOU | J25: =VLOOKUP('E-impôts'!A25,Feuil2!$A$1:$AA$298,19,0) -> 708414136 | K25: =VLOOKUP('E-impôts'!A25,Feuil2!$A$1:$AA$298,9,0) -> CI-ABJ-03-B17-00080 | L25: =VLOOKUP('E-impôts'!A25,Feuil2!$A$1:$AA$298,15,0) -> II Plateaux III | M25: =VLOOKUP('E-impôts'!A25,Feuil2!$A$1:$AA$298,13,0) -> AO | N25: =VLOOKUP('E-impôts'!A25,Feuil2!$A$1:$AA$298,14,0) -> 13 | O25: P850400 | P25: =VLOOKUP(A25,Feuil2!$A$1:$AA$298,17,0) -> 10000000
A26: 1906134N | B26: UNIDIS INTER | C26: =VLOOKUP('E-impôts'!A26,Feuil2!$A$1:$AA$298,4,0) -> #N/A | D26: 43858 | E26: =VLOOKUP('E-impôts'!A26,Feuil2!$A$1:$AA$298,8,0) -> DCK-CGA2021-Q147 | F26: =VLOOKUP('E-impôts'!A26,Feuil2!$A$1:$AA$298,24,0) -> 01 BP 10683 ABJ 01 | G26: =VLOOKUP('E-impôts'!A26,Feuil2!$A$1:$AA$298,11,0) -> RME | H26: =VLOOKUP('E-impôts'!A26,Feuil2!$A$1:$AA$298,10,0) -> SARL | I26: =VLOOKUP('E-impôts'!A26,Feuil2!$A$1:$AA$298,5,0) -> YOUZAN AYA ROSINE-LEA Epse N'GUESSAN | J26: =VLOOKUP('E-impôts'!A26,Feuil2!$A$1:$AA$298,19,0) -> 749933263 | K26: =VLOOKUP('E-impôts'!A26,Feuil2!$A$1:$AA$298,9,0) -> CI-ABJ-2019-B-02186 | L26: =VLOOKUP('E-impôts'!A26,Feuil2!$A$1:$AA$298,15,0) -> II Pateaux I | M26: =VLOOKUP('E-impôts'!A26,Feuil2!$A$1:$AA$298,13,0) -> ND | N26: =VLOOKUP('E-impôts'!A26,Feuil2!$A$1:$AA$298,14,0) -> ND | O26: =VLOOKUP('E-impôts'!A26,Feuil2!$A$1:$AA$298,16,0) -> IND1504 | P26: =VLOOKUP(A26,Feuil2!$A$1:$AA$298,17,0) -> 1000000
A27: 2303775P | B27: TRAZIE LOU NABOUE NADEGE | C27: =VLOOKUP('E-impôts'!A27,Feuil2!$A$1:$AA$298,4,0) -> MARIAME | D27: 45315 | E27: =VLOOKUP('E-impôts'!A27,Feuil2!$A$1:$AA$298,8,0) -> DCK-CGA2024-A023 | F27: =VLOOKUP('E-impôts'!A27,Feuil2!$A$1:$AA$298,24,0) -> FAYA | G27: =VLOOKUP('E-impôts'!A27,Feuil2!$A$1:$AA$298,11,0) -> TEE | H27: =VLOOKUP('E-impôts'!A27,Feuil2!$A$1:$AA$298,10,0) -> ENTREPRISE INDIVIDUELLE | I27: =VLOOKUP('E-impôts'!A27,Feuil2!$A$1:$AA$298,5,0) -> TRAZIE LOU NABOUE NADEGE | J27: =VLOOKUP('E-impôts'!A27,Feuil2!$A$1:$AA$298,19,0) -> 709899557 | K27: =VLOOKUP('E-impôts'!A27,Feuil2!$A$1:$AA$298,9,0) -> CI-ABJ-03-2023-A10-02618 | L27: =VLOOKUP('E-impôts'!A27,Feuil2!$A$1:$AA$298,15,0) -> II Plateaux III | M27: =VLOOKUP('E-impôts'!A27,Feuil2!$A$1:$AA$298,13,0) -> VZ | N27: =VLOOKUP('E-impôts'!A27,Feuil2!$A$1:$AA$298,14,0) -> 201 | O27: =VLOOKUP('E-impôts'!A27,Feuil2!$A$1:$AA$298,16,0) -> SCE19001 | P27: =VLOOKUP(A27,Feuil2!$A$1:$AA$298,17,0) -> 1000000
A28: 0313308U | B28: TRAZIE Houlie Lucie | C28: =VLOOKUP('E-impôts'!A28,Feuil2!$A$1:$AA$298,4,0) -> CABINET CFA | D28: 44589 | E28: =VLOOKUP('E-impôts'!A28,Feuil2!$A$1:$AA$298,8,0) -> DCK-CGA2022-J056 | F28: =VLOOKUP('E-impôts'!A28,Feuil2!$A$1:$AA$298,24,0) -> COCODY II PLATEAUX AGHIEN | G28: =VLOOKUP('E-impôts'!A28,Feuil2!$A$1:$AA$298,11,0) -> TEE | H28: =VLOOKUP('E-impôts'!A28,Feuil2!$A$1:$AA$298,10,0) -> ENTREPRISE INDIVIDUELLE | I28: =VLOOKUP('E-impôts'!A28,Feuil2!$A$1:$AA$298,5,0) -> NULL | J28: =VLOOKUP('E-impôts'!A28,Feuil2!$A$1:$AA$298,19,0) -> 2722426745 | K28: =VLOOKUP('E-impôts'!A28,Feuil2!$A$1:$AA$298,9,0) -> NULL | L28: =VLOOKUP('E-impôts'!A28,Feuil2!$A$1:$AA$298,15,0) -> II Plateaux III | M28: =VLOOKUP('E-impôts'!A28,Feuil2!$A$1:$AA$298,13,0) -> NULL | N28: =VLOOKUP('E-impôts'!A28,Feuil2!$A$1:$AA$298,14,0) -> NULL | O28: =VLOOKUP('E-impôts'!A28,Feuil2!$A$1:$AA$298,16,0) -> NULL | P28: =VLOOKUP(A28,Feuil2!$A$1:$AA$298,17,0) -> NULL
A29: 2016878X | B29: TRAN TRONG HOANG | C29: =VLOOKUP('E-impôts'!A29,Feuil2!$A$1:$AA$298,4,0) -> Abdoulaye | D29: 45315 | E29: =VLOOKUP('E-impôts'!A29,Feuil2!$A$1:$AA$298,8,0) -> DCK-CGA2024-A022 | F29: =VLOOKUP('E-impôts'!A29,Feuil2!$A$1:$AA$298,24,0) -> BINGERVILLE COUP DE FREIN | G29: =VLOOKUP('E-impôts'!A29,Feuil2!$A$1:$AA$298,11,0) -> TEE | H29: =VLOOKUP('E-impôts'!A29,Feuil2!$A$1:$AA$298,10,0) -> ENTREPRISE INDIVIDUELLE | I29: =VLOOKUP('E-impôts'!A29,Feuil2!$A$1:$AA$298,5,0) -> TRAN TRONG HOANG | J29: =VLOOKUP('E-impôts'!A29,Feuil2!$A$1:$AA$298,19,0) -> 708537463 | K29: =VLOOKUP('E-impôts'!A29,Feuil2!$A$1:$AA$298,9,0) -> CI-ABJ-2018-A-05921 | L29: =VLOOKUP('E-impôts'!A29,Feuil2!$A$1:$AA$298,15,0) -> Bingerville | M29: =VLOOKUP('E-impôts'!A29,Feuil2!$A$1:$AA$298,13,0) -> 0 | N29: =VLOOKUP('E-impôts'!A29,Feuil2!$A$1:$AA$298,14,0) -> 0 | O29: =VLOOKUP('E-impôts'!A29,Feuil2!$A$1:$AA$298,16,0) -> SCE0204 | P29: =VLOOKUP(A29,Feuil2!$A$1:$AA$298,17,0) -> 1000000
A30: 2244784P | B30: TRADE OF ROYAL MAX | C30: =VLOOKUP('E-impôts'!A30,Feuil2!$A$1:$AA$298,4,0) -> #N/A | D30: 45318 | E30: =VLOOKUP('E-impôts'!A30,Feuil2!$A$1:$AA$298,8,0) -> DCK-CGA2024-A025 | F30: =VLOOKUP('E-impôts'!A30,Feuil2!$A$1:$AA$298,24,0) -> 2 PLATEAUX VALLON | G30: =VLOOKUP('E-impôts'!A30,Feuil2!$A$1:$AA$298,11,0) -> TEE | H30: =VLOOKUP('E-impôts'!A30,Feuil2!$A$1:$AA$298,10,0) -> SARL | I30: =VLOOKUP('E-impôts'!A30,Feuil2!$A$1:$AA$298,5,0) -> LI XIAOMING | J30: =VLOOKUP('E-impôts'!A30,Feuil2!$A$1:$AA$298,19,0) -> 711129045 | K30: =VLOOKUP('E-impôts'!A30,Feuil2!$A$1:$AA$298,9,0) -> CI-ABJ-03-2022-B13-10636 | L30: =VLOOKUP('E-impôts'!A30,Feuil2!$A$1:$AA$298,15,0) -> II Plateaux III | M30: =VLOOKUP('E-impôts'!A30,Feuil2!$A$1:$AA$298,13,0) -> N/D | N30: =VLOOKUP('E-impôts'!A30,Feuil2!$A$1:$AA$298,14,0) -> N/D | O30: =VLOOKUP('E-impôts'!A30,Feuil2!$A$1:$AA$298,16,0) -> N/D | P30: =VLOOKUP(A30,Feuil2!$A$1:$AA$298,17,0) -> 1Â 000 000
A31: 1707216G | B31: TOUNDE QUICAILLERIE | C31: =VLOOKUP('E-impôts'!A31,Feuil2!$A$1:$AA$298,4,0) -> ZADI | D31: 44574 | E31: =VLOOKUP('E-impôts'!A31,Feuil2!$A$1:$AA$298,8,0) -> DCK-CGA2020-A074 | F31: =VLOOKUP('E-impôts'!A31,Feuil2!$A$1:$AA$298,24,0) -> BINGERVILLE | G31: =VLOOKUP('E-impôts'!A31,Feuil2!$A$1:$AA$298,11,0) -> TEE | H31: =VLOOKUP('E-impôts'!A31,Feuil2!$A$1:$AA$298,10,0) -> ENTREPRISE INDIVIDUELLE | I31: =VLOOKUP('E-impôts'!A31,Feuil2!$A$1:$AA$298,5,0) -> NULL | J31: =VLOOKUP('E-impôts'!A31,Feuil2!$A$1:$AA$298,19,0) -> 506899413 | K31: =VLOOKUP('E-impôts'!A31,Feuil2!$A$1:$AA$298,9,0) -> NULL | L31: =VLOOKUP('E-impôts'!A31,Feuil2!$A$1:$AA$298,15,0) -> Bingerville | M31: =VLOOKUP('E-impôts'!A31,Feuil2!$A$1:$AA$298,13,0) -> NULL | N31: =VLOOKUP('E-impôts'!A31,Feuil2!$A$1:$AA$298,14,0) -> NULL | O31: =VLOOKUP('E-impôts'!A31,Feuil2!$A$1:$AA$298,16,0) -> NULL | P31: =VLOOKUP(A31,Feuil2!$A$1:$AA$298,17,0) -> NULL
A32: 2245408S | B32: TENAN GROUP | C32: =VLOOKUP('E-impôts'!A32,Feuil2!$A$1:$AA$298,4,0) -> #N/A | D32: 45316 | E32: =VLOOKUP('E-impôts'!A32,Feuil2!$A$1:$AA$298,8,0) -> DCK-CGA2024-A030 | F32: =VLOOKUP('E-impôts'!A32,Feuil2!$A$1:$AA$298,24,0) -> COCODY 7Ã¨me tranche | G32: =VLOOKUP('E-impôts'!A32,Feuil2!$A$1:$AA$298,11,0) -> TEE | H32: =VLOOKUP('E-impôts'!A32,Feuil2!$A$1:$AA$298,10,0) -> SARL | I32: =VLOOKUP('E-impôts'!A32,Feuil2!$A$1:$AA$298,5,0) -> KONE TENAN ISSA | J32: =VLOOKUP('E-impôts'!A32,Feuil2!$A$1:$AA$298,19,0) -> 707999183 | K32: =VLOOKUP('E-impôts'!A32,Feuil2!$A$1:$AA$298,9,0) -> CI-ABJ-03-2022-B13-11335 | L32: =VLOOKUP('E-impôts'!A32,Feuil2!$A$1:$AA$298,15,0) -> Riviera II | M32: =VLOOKUP('E-impôts'!A32,Feuil2!$A$1:$AA$298,13,0) -> 0 | N32: =VLOOKUP('E-impôts'!A32,Feuil2!$A$1:$AA$298,14,0) -> 0 | O32: =VLOOKUP('E-impôts'!A32,Feuil2!$A$1:$AA$298,16,0) -> 0 | P32: =VLOOKUP(A32,Feuil2!$A$1:$AA$298,17,0) -> 1000000
A33: 0720702T | B33: TANOH EPSE AKOUASSA AFFOUE | C33: =VLOOKUP('E-impôts'!A33,Feuil2!$A$1:$AA$298,4,0) -> #N/A | D33: 43859 | E33: =VLOOKUP('E-impôts'!A33,Feuil2!$A$1:$AA$298,8,0) -> #N/A | F33: =VLOOKUP('E-impôts'!A33,Feuil2!$A$1:$AA$298,24,0) -> #N/A | G33: =VLOOKUP('E-impôts'!A33,Feuil2!$A$1:$AA$298,11,0) -> #N/A | H33: =VLOOKUP('E-impôts'!A33,Feuil2!$A$1:$AA$298,10,0) -> #N/A | I33: =VLOOKUP('E-impôts'!A33,Feuil2!$A$1:$AA$298,5,0) -> #N/A | J33: =VLOOKUP('E-impôts'!A33,Feuil2!$A$1:$AA$298,19,0) -> #N/A | K33: =VLOOKUP('E-impôts'!A33,Feuil2!$A$1:$AA$298,9,0) -> #N/A | L33: =VLOOKUP('E-impôts'!A33,Feuil2!$A$1:$AA$298,15,0) -> #N/A | M33: =VLOOKUP('E-impôts'!A33,Feuil2!$A$1:$AA$298,13,0) -> #N/A | N33: =VLOOKUP('E-impôts'!A33,Feuil2!$A$1:$AA$298,14,0) -> #N/A | O33: =VLOOKUP('E-impôts'!A33,Feuil2!$A$1:$AA$298,16,0) -> #N/A | P33: =VLOOKUP(A33,Feuil2!$A$1:$AA$298,17,0) -> #N/A
A34: 1810218D | B34: TALENT SCHOOL OF BUSINESS | C34: =VLOOKUP('E-impôts'!A34,Feuil2!$A$1:$AA$298,4,0) -> #N/A | D34: 45315 | E34: =VLOOKUP('E-impôts'!A34,Feuil2!$A$1:$AA$298,8,0) -> DCK-CGA2024-A019 | F34: =VLOOKUP('E-impôts'!A34,Feuil2!$A$1:$AA$298,24,0) -> II PLATEAUX VALLONS | G34: =VLOOKUP('E-impôts'!A34,Feuil2!$A$1:$AA$298,11,0) -> TEE | H34: =VLOOKUP('E-impôts'!A34,Feuil2!$A$1:$AA$298,10,0) -> SAS | I34: =VLOOKUP('E-impôts'!A34,Feuil2!$A$1:$AA$298,5,0) -> ZARROUK MEHDI | J34: =VLOOKUP('E-impôts'!A34,Feuil2!$A$1:$AA$298,19,0) -> 778292924 | K34: =VLOOKUP('E-impôts'!A34,Feuil2!$A$1:$AA$298,9,0) -> CI-ABJ03-2023-M-15026 | L34: =VLOOKUP('E-impôts'!A34,Feuil2!$A$1:$AA$298,15,0) -> II Pateaux II | M34: =VLOOKUP('E-impôts'!A34,Feuil2!$A$1:$AA$298,13,0) -> LS | N34: =VLOOKUP('E-impôts'!A34,Feuil2!$A$1:$AA$298,14,0) -> 297 | O34: =VLOOKUP('E-impôts'!A34,Feuil2!$A$1:$AA$298,16,0) -> SCE1501 | P34: =VLOOKUP(A34,Feuil2!$A$1:$AA$298,17,0) -> 10000000
A35: 2300836U | B35: SYNERGY PHARMA | C35: =VLOOKUP('E-impôts'!A35,Feuil2!$A$1:$AA$298,4,0) -> #N/A | D35: 45321 | E35: =VLOOKUP('E-impôts'!A35,Feuil2!$A$1:$AA$298,8,0) -> DCK-CGA2024-A081 | F35: =VLOOKUP('E-impôts'!A35,Feuil2!$A$1:$AA$298,24,0) -> COCODY RIVIERA FAYA | G35: =VLOOKUP('E-impôts'!A35,Feuil2!$A$1:$AA$298,11,0) -> TEE | H35: =VLOOKUP('E-impôts'!A35,Feuil2!$A$1:$AA$298,10,0) -> SARL | I35: =VLOOKUP('E-impôts'!A35,Feuil2!$A$1:$AA$298,5,0) -> DEBRIMOU DANIELLE RENEE | J35: =VLOOKUP('E-impôts'!A35,Feuil2!$A$1:$AA$298,19,0) -> 142900455 | K35: =VLOOKUP('E-impôts'!A35,Feuil2!$A$1:$AA$298,9,0) -> CI-ABJ-03-2023-B12-01206 | L35: =VLOOKUP('E-impôts'!A35,Feuil2!$A$1:$AA$298,15,0) -> Riviera II | M35: =VLOOKUP('E-impôts'!A35,Feuil2!$A$1:$AA$298,13,0) -> HR | N35: =VLOOKUP('E-impôts'!A35,Feuil2!$A$1:$AA$298,14,0) -> 44 | O35: I550000 | P35: =VLOOKUP(A35,Feuil2!$A$1:$AA$298,17,0) -> 5000000
A36: 2019321T | B36: SYMBIOZ IMMOBILIER | C36: =VLOOKUP('E-impôts'!A36,Feuil2!$A$1:$AA$298,4,0) -> CABINET CFA | D36: 44224 | E36: =VLOOKUP('E-impôts'!A36,Feuil2!$A$1:$AA$298,8,0) -> DCK-CGA2021-Q168 | F36: =VLOOKUP('E-impôts'!A36,Feuil2!$A$1:$AA$298,24,0) -> COCODY, RIVIERA PALMERAIE | G36: =VLOOKUP('E-impôts'!A36,Feuil2!$A$1:$AA$298,11,0) -> TEE | H36: =VLOOKUP('E-impôts'!A36,Feuil2!$A$1:$AA$298,10,0) -> SARL | I36: =VLOOKUP('E-impôts'!A36,Feuil2!$A$1:$AA$298,5,0) -> NULL | J36: =VLOOKUP('E-impôts'!A36,Feuil2!$A$1:$AA$298,19,0) -> 767552335 | K36: =VLOOKUP('E-impôts'!A36,Feuil2!$A$1:$AA$298,9,0) -> NULL | L36: =VLOOKUP('E-impôts'!A36,Feuil2!$A$1:$AA$298,15,0) -> Riviera I | M36: =VLOOKUP('E-impôts'!A36,Feuil2!$A$1:$AA$298,13,0) -> NULL | N36: =VLOOKUP('E-impôts'!A36,Feuil2!$A$1:$AA$298,14,0) -> NULL | O36: =VLOOKUP('E-impôts'!A36,Feuil2!$A$1:$AA$298,16,0) -> NULL | P36: =VLOOKUP(A36,Feuil2!$A$1:$AA$298,17,0) -> NULL
B37: STENO GROUP | C37: =VLOOKUP('E-impôts'!A37,Feuil2!$A$1:$AA$298,4,0) -> #N/A | D37: 44589 | E37: =VLOOKUP('E-impôts'!A37,Feuil2!$A$1:$AA$298,8,0) -> #N/A | F37: =VLOOKUP('E-impôts'!A37,Feuil2!$A$1:$AA$298,24,0) -> #N/A | G37: =VLOOKUP('E-impôts'!A37,Feuil2!$A$1:$AA$298,11,0) -> #N/A | H37: =VLOOKUP('E-impôts'!A37,Feuil2!$A$1:$AA$298,10,0) -> #N/A | I37: =VLOOKUP('E-impôts'!A37,Feuil2!$A$1:$AA$298,5,0) -> #N/A | J37: =VLOOKUP('E-impôts'!A37,Feuil2!$A$1:$AA$298,19,0) -> #N/A | K37: =VLOOKUP('E-impôts'!A37,Feuil2!$A$1:$AA$298,9,0) -> #N/A | L37: =VLOOKUP('E-impôts'!A37,Feuil2!$A$1:$AA$298,15,0) -> #N/A | M37: =VLOOKUP('E-impôts'!A37,Feuil2!$A$1:$AA$298,13,0) -> #N/A | N37: =VLOOKUP('E-impôts'!A37,Feuil2!$A$1:$AA$298,14,0) -> #N/A | O37: =VLOOKUP('E-impôts'!A37,Feuil2!$A$1:$AA$298,16,0) -> #N/A | P37: =VLOOKUP(A37,Feuil2!$A$1:$AA$298,17,0) -> #N/A
A38: 1430635S | B38: STE DE PRODUCTION ET DE DISTRI | C38: =VLOOKUP('E-impôts'!A38,Feuil2!$A$1:$AA$298,4,0) -> #N/A | D38: 45322 | E38: =VLOOKUP('E-impôts'!A38,Feuil2!$A$1:$AA$298,8,0) -> DCK-CGA2024-A002 | F38: =VLOOKUP('E-impôts'!A38,Feuil2!$A$1:$AA$298,24,0) -> ABIDJAN COCODY ANGRE STAR 6 | G38: =VLOOKUP('E-impôts'!A38,Feuil2!$A$1:$AA$298,11,0) -> TEE | H38: =VLOOKUP('E-impôts'!A38,Feuil2!$A$1:$AA$298,10,0) -> SARL | I38: =VLOOKUP('E-impôts'!A38,Feuil2!$A$1:$AA$298,5,0) -> OSNOU YOBOUET EDJEM AWA JACQUELINE EPSE DJIRE | J38: =VLOOKUP('E-impôts'!A38,Feuil2!$A$1:$AA$298,19,0) -> 07 59 37 49 20 | K38: =VLOOKUP('E-impôts'!A38,Feuil2!$A$1:$AA$298,9,0) -> CI-ABI-2014-B-8078 | L38: =VLOOKUP('E-impôts'!A38,Feuil2!$A$1:$AA$298,15,0) -> II Pateaux I | M38: =VLOOKUP('E-impôts'!A38,Feuil2!$A$1:$AA$298,13,0) -> DO | N38: =VLOOKUP('E-impôts'!A38,Feuil2!$A$1:$AA$298,14,0) -> 99 | O38: =VLOOKUP('E-impôts'!A38,Feuil2!$A$1:$AA$298,16,0) -> CCE1701 | P38: =VLOOKUP(A38,Feuil2!$A$1:$AA$298,17,0) -> 1000000
A39: 1336628G | B39: SORO FOUNGNIGUE | C39: =VLOOKUP('E-impôts'!A39,Feuil2!$A$1:$AA$298,4,0) -> CABINET CFA | D39: 43871 | E39: =VLOOKUP('E-impôts'!A39,Feuil2!$A$1:$AA$298,8,0) -> DCK-CGA2020-A100 | F39: =VLOOKUP('E-impôts'!A39,Feuil2!$A$1:$AA$298,24,0) -> COCODY CAFFEIER II | G39: =VLOOKUP('E-impôts'!A39,Feuil2!$A$1:$AA$298,11,0) -> TEE | H39: =VLOOKUP('E-impôts'!A39,Feuil2!$A$1:$AA$298,10,0) -> ENTREPRISE INDIVIDUELLE | I39: =VLOOKUP('E-impôts'!A39,Feuil2!$A$1:$AA$298,5,0) -> NULL | J39: =VLOOKUP('E-impôts'!A39,Feuil2!$A$1:$AA$298,19,0) -> 707347436 | K39: =VLOOKUP('E-impôts'!A39,Feuil2!$A$1:$AA$298,9,0) -> NULL | L39: =VLOOKUP('E-impôts'!A39,Feuil2!$A$1:$AA$298,15,0) -> II Plateaux I | M39: =VLOOKUP('E-impôts'!A39,Feuil2!$A$1:$AA$298,13,0) -> NULL | N39: =VLOOKUP('E-impôts'!A39,Feuil2!$A$1:$AA$298,14,0) -> NULL | O39: =VLOOKUP('E-impôts'!A39,Feuil2!$A$1:$AA$298,16,0) -> NULL | P39: =VLOOKUP(A39,Feuil2!$A$1:$AA$298,17,0) -> NULL
A40: 2241904N | B40: SOFT INGENIERIE | C40: =VLOOKUP('E-impôts'!A40,Feuil2!$A$1:$AA$298,4,0) -> #N/A | D40: 45322 | E40: =VLOOKUP('E-impôts'!A40,Feuil2!$A$1:$AA$298,8,0) -> DCK-CGA2024-A052 | F40: =VLOOKUP('E-impôts'!A40,Feuil2!$A$1:$AA$298,24,0) -> COCODY RIVIERA ABATTA NOUVEAU GOUDRON VERS BLD SIR CITE PRESTIGE 2 | G40: =VLOOKUP('E-impôts'!A40,Feuil2!$A$1:$AA$298,11,0) -> TEE | H40: =VLOOKUP('E-impôts'!A40,Feuil2!$A$1:$AA$298,10,0) -> SARL | I40: =VLOOKUP('E-impôts'!A40,Feuil2!$A$1:$AA$298,5,0) -> COULIBALY ISMAEL | J40: =VLOOKUP('E-impôts'!A40,Feuil2!$A$1:$AA$298,19,0) -> 707336407 | K40: =VLOOKUP('E-impôts'!A40,Feuil2!$A$1:$AA$298,9,0) -> CI-ABJ-03-2022-B13-04073 | L40: =VLOOKUP('E-impôts'!A40,Feuil2!$A$1:$AA$298,15,0) -> Riviera II | M40: =VLOOKUP('E-impôts'!A40,Feuil2!$A$1:$AA$298,13,0) -> 0 | N40: =VLOOKUP('E-impôts'!A40,Feuil2!$A$1:$AA$298,14,0) -> 0 | O40: =VLOOKUP('E-impôts'!A40,Feuil2!$A$1:$AA$298,16,0) -> SCE0801 | P40: =VLOOKUP(A40,Feuil2!$A$1:$AA$298,17,0) -> 1000000
...

Sheet Feuil2
A1: numcc | B1: userid | C1: company | D1: Portefeuilles | E1: identification | F1: fonction | G1: numcga | H1: numadh | I1: numrccm | J1: formjurid | K1: regime | L1: acti_prin | M1: section | N1: parcelle | O1: imp_centre | P1: codeacti | Q1: montcapit | R1: emailetprse | S1: phonenumber | T1: country | U1: city | V1: zip | W1: state | X1: address | Y1: website | Z1: datecreated | AA1: active
A2: 4105181N | B2: 1 | C2: HONDE REINE BELLE | D2: =VLOOKUP('[1]tblclients (1)'!A2,[1]Feuil1!$A$1:$G$203,4,0) -> DCK | E2: NULL | F2: NULL | G2: DCK-001 | H2: DCK-CGA2019-A026 | I2: NULL | J2: ENTREPRISE INDIVIDUELLE | K2: TEE | L2: NULL | M2: NULL | N2: NULL | O2: II Plateaux II | P2: NULL | Q2: NULL | R2: NULL | S2: 707059199 | T2: 54 | U2: Abidjan | V2: NULL | W2: NULL | X2: COCODY II PLATEAUX VALLONS | Y2: NULL | Z2: 43466 | AA2: 1
A3: 1526919K | B3: 2 | C3: GOLY ADJOUA EDITH ESTELLE | D3: =VLOOKUP('[1]tblclients (1)'!A3,[1]Feuil1!$A$1:$G$203,4,0) -> DCK | E3: GOLY ADJOUA EDITH ESTELLE | F3: Exploitante individuelle | G3: DCK-002 | H3: DCK-CGA2019-A013 | I3: CI-ABJ-2015-A-3981 | J3: ENTREPRISE INDIVIDUELLE | K3: TEE | L3: Fourniture de bureau | M3: EV | N3: 541 | O3: II Plateaux III | P3: CCE1501 | R3: N/D | S3: 758840340 | T3: 54 | U3: Abidjan | V3: 09 BP 1976 ABID | W3: N/D | X3: COCODY RIVERA BONOUMIN | Y3: N/D | Z3: 43466 | AA3: 1
A4: 1435907M | B4: 3 | C4: ETTE DJEKET CORINE EPSE AVOAKA | D4: =VLOOKUP('[1]tblclients (1)'!A4,[1]Feuil1!$A$1:$G$203,4,0) -> DCK | E4: NULL | F4: NULL | G4: DCK-003 | H4: DCK-CGA2020-A050 | I4: NULL | J4: ENTREPRISE INDIVIDUELLE | K4: TEE | L4: NULL | M4: NULL | N4: NULL | O4: Cocody | P4: NULL | Q4: NULL | R4: NULL | S4: 707114141 | T4: 54 | U4: Abidjan | V4: NULL | W4: NULL | X4: COCODY BLOCKAUSS | Y4: NULL | Z4: 43471 | AA4: 1
A5: 0323332D | B5: 4 | C5: KONATE Harouna | D5: =VLOOKUP('[1]tblclients (1)'!A5,[1]Feuil1!$A$1:$G$203,4,0) -> DCK | E5: NULL | F5: NULL | G5: DCK-004 | H5: DCK-CGA2019-A039 | I5: NULL | J5: ENTREPRISE INDIVIDUELLE | K5: TEE | L5: NULL | M5: NULL | N5: NULL | O5: Cocody | P5: NULL | Q5: NULL | R5: NULL | S5: 707941178 | T5: 54 | U5: Abidjan | V5: NULL | W5: NULL | X5: COCODY SAINT JEAN | Y5: NULL | Z5: 43479 | AA5: 1
A6: 1507261D | B6: 5 | C6: ZANGRE HAROUNA | D6: =VLOOKUP('[1]tblclients (1)'!A6,[1]Feuil1!$A$1:$G$203,4,0) -> DCK | E6: NULL | F6: NULL | G6: DCK-005 | H6: DCK-CGA2019-A024 | I6: NULL | J6: ENTREPRISE INDIVIDUELLE | K6: TEE | L6: NULL | M6: NULL | N6: NULL | O6: Cocody | P6: NULL | Q6: NULL | R6: NULL | S6: 505843545 | T6: 54 | U6: Abidjan | V6: NULL | W6: NULL | X6: COCODY SAINT JEAN | Y6: NULL | Z6: 43479 | AA6: 1
A7: 1414480Q | B7: 6 | C7: OUEDRAOGO YOUSSOUF | D7: =VLOOKUP('[1]tblclients (1)'!A7,[1]Feuil1!$A$1:$G$203,4,0) -> DCK | E7: NULL | F7: NULL | G7: DCK-006 | H7: DCK-CGA2019-A023 | I7: NULL | J7: ENTREPRISE INDIVIDUELLE | K7: TEE | L7: NULL | M7: NULL | N7: NULL | O7: Cocody | P7: NULL | Q7: NULL | R7: NULL | S7: 707582591 | T7: 54 | U7: Abidjan | V7: NULL | W7: NULL | X7: COCODY SAINT JEAN | Y7: NULL | Z7: 43479 | AA7: 1
A8: 1827528R | B8: 7 | C8: YAGUERA & COMPAGNIE | D8: =VLOOKUP('[1]tblclients (1)'!A8,[1]Feuil1!$A$1:$G$203,4,0) -> DCK | E8: NULL | F8: NULL | G8: DCK-007 | H8: DCK-CGA2019-A007 | I8: NULL | J8: SARL | K8: TEE | L8: NULL | M8: NULL | N8: NULL | O8: II Plateaux I | P8: NULL | Q8: NULL | R8: NULL | S8: 789844008 | T8: 54 | U8: Abidjan | V8: NULL | W8: NULL | X8: COCODY ANGRE 7E TRANCHE | Y8: NULL | Z8: 43479 | AA8: 1
A9: 1619903H | B9: 8 | C9: NEDJMA SARLU | D9: =VLOOKUP('[1]tblclients (1)'!A9,[1]Feuil1!$A$1:$G$203,4,0) -> DCK | E9: NULL | F9: NULL | G9: DCK-008 | H9: DCK-CGA2019-A029 | I9: NULL | J9: SARL | K9: TEE | L9: NULL | M9: NULL | N9: NULL | O9: II Plateaux I | P9: NULL | Q9: NULL | R9: NULL | S9: 707070102 | T9: 54 | U9: Abidjan | V9: NULL | W9: NULL | X9: COCODY RIVIERA BONOUMIN | Y9: NULL | Z9: 43479 | AA9: 1
A10: 1530324W | B10: 9 | C10: CONCEPT IMAGE | D10: =VLOOKUP('[1]tblclients (1)'!A10,[1]Feuil1!$A$1:$G$203,4,0) -> DCK | G10: DCK-009 | H10: DCK-CGA2019-B036 | J10: SARL | K10: RME | O10: II Plateaux II | S10: 101017474 | T10: 54 | U10: Abidjan | X10: COCODY II PLATAUX SIDECI | Z10: 43479 | AA10: 1
A11: 0735268S | B11: 10 | C11: COFFI MARIE COLETTE | D11: =VLOOKUP('[1]tblclients (1)'!A11,[1]Feuil1!$A$1:$G$203,4,0) -> DCK | E11: NULL | F11: NULL | G11: DCK-010 | H11: DCK-CGA2019-A022 | I11: NULL | J11: ENTREPRISE INDIVIDUELLE | K11: TEE | L11: NULL | M11: NULL | N11: NULL | O11: II Plateaux II | P11: NULL | Q11: NULL | R11: NULL | S11: 707435252 | T11: 54 | U11: Abidjan | V11: NULL | W11: NULL | X11: COCODY VALLON | Y11: NULL | Z11: 43479 | AA11: 1
A12: 9410895U | B12: 11 | C12: YERE LOU EPSE YACE NENENAN BLANCHE | D12: =VLOOKUP('[1]tblclients (1)'!A12,[1]Feuil1!$A$1:$G$203,4,0) -> DCK | E12: NULL | F12: NULL | G12: DCK-011 | H12: DCK-CGA2019-A040 | I12: NULL | J12: ENTREPRISE INDIVIDUELLE | K12: TEE | L12: NULL | M12: NULL | N12: NULL | O12: II Plateaux II | P12: NULL | Q12: NULL | R12: NULL | S12: 707070392 | T12: 54 | U12: Abidjan | V12: NULL | W12: NULL | X12: COCODY II PLATEAUX VALLON | Y12: NULL | Z12: 43479 | AA12: 1
A13: 1307492V | B13: 12 | C13: N'GUESSAN ATTIEGOUA ANNE ELLA | D13: =VLOOKUP('[1]tblclients (1)'!A13,[1]Feuil1!$A$1:$G$203,4,0) -> DCK | E13: NULL | F13: NULL | G13: DCK-012 | H13: DCK-CGA2019-A010 | I13: NULL | J13: ENTREPRISE INDIVIDUELLE | K13: TEE | L13: NULL | M13: NULL | N13: NULL | O13: II Plateaux II | P13: NULL | Q13: NULL | R13: NULL | S13: 708048295 | T13: 54 | U13: Abidjan | V13: NULL | W13: NULL | X13: II PLATEUX VALLON | Y13: NULL | Z13: 43479 | AA13: 1
A14: 1220791C | B14: 13 | C14: KOUAME KONAN FIRMIN | D14: =VLOOKUP('[1]tblclients (1)'!A14,[1]Feuil1!$A$1:$G$203,4,0) -> DCK | E14: KOUAME KONAN FIRMIN | F14: Exploitant individuel | G14: DCK-013 | H14: DCK-CGA2019-A016 | I14: N/D | J14: ENTREPRISE INDIVIDUELLE | K14: TEE | L14: TRAVAUX DE TELECOM
A15: 1321944W | B15: 14 | C15: KIMOU ERIC HERVE | D15: =VLOOKUP('[1]tblclients (1)'!A15,[1]Feuil1!$A$1:$G$203,4,0) -> DCK | E15: KIMOU ERIC | F15: Exploitant individuel | G15: DCK-014 | H15: DCK-CGA2019-A019 | J15: ENTREPRISE INDIVIDUELLE | K15: TEE | S15: 101800240 | T15: 54 | U15: Abidjan | X15: COCODY RIVIERA BONOUMIN | Z15: 43479 | AA15: 1
A16: 0709432N | B16: 15 | C16: YIRA SIAKA | D16: =VLOOKUP('[1]tblclients (1)'!A16,[1]Feuil1!$A$1:$G$203,4,0) -> DCK | E16: YIRA SIAKA | F16: PROPRIETAIRE | G16: DCK-015 | H16: DCK-CGA2019-A005 | I16: 09 BP 2525 ABIDJAN 09 | J16: ENTREPRISE INDIVIDUELLE | K16: TEE | L16: Transport et prestation de services | M16: N/D | N16: N/D | O16: II Plateaux III | P16: SCE2103 | Q16: 6000000 | R16: N/D | S16: 757740598 | T16: 54 | U16: Abidjan | V16: 225 | W16: N/D | X16: COCODY RIVIERA BONOUMIN | Z16: 43479 | AA16: 1
A17: 0514603E | B17: 16 | C17: ZALLE MAHAMOUD | D17: =VLOOKUP('[1]tblclients (1)'!A17,[1]Feuil1!$A$1:$G$203,4,0) -> DCK | E17: ZALLE MAHAMOUD | F17: Exploitant Individuel | G17: DCK-016 | H17: DCK-CGA2019-A025 | I17: CI-ABJ-2011-A-6598 | J17: ENTREPRISE INDIVIDUELLE | K17: TEE | L17: QUINCAILLERIE | M17: N/D | N17: N/D | O17: II Plateaux Djibi | P17: N/D | R17: N/D | S17: 505938989 | T17: 54 | U17: Abidjan | V17: N/D | W17: N/D | X17: COCODY ANGRE-DJIBI | Y17: N/D | Z17: 43479 | AA17: 1
A18: 1526973R | B18: 17 | C18: CENTRE D'EDUCATION ROUTIERE EN COTE D'IVOIRE | D18: =VLOOKUP('[1]tblclients (1)'!A18,[1]Feuil1!$A$1:$G$203,4,0) -> DCK | E18: NULL | F18: NULL | G18: DCK-017 | H18: DCK-CGA2019-B031 | I18: NULL | J18: SARL | K18: RME | L18: NULL | M18: NULL | N18: NULL | O18: Riviera I | P18: NULL | Q18: NULL | R18: NULL | S18: 757893651 | T18: 54 | U18: Abidjan | V18: NULL | W18: NULL | X18: RIVIERA LES JARDINS | Y18: NULL | Z18: 43479 | AA18: 1
A19: 1019140H | B19: 18 | C19: CISSE MOUSSA | D19: =VLOOKUP('[1]tblclients (1)'!A19,[1]Feuil1!$A$1:$G$203,4,0) -> DCK | E19: NULL | F19: NULL | G19: DCK-018 | H19: DCK-CGA2019-A001 | I19: NULL | J19: ENTREPRISE INDIVIDUELLE | K19: TEE | L19: NULL | M19: NULL | N19: NULL | O19: Riviera II | P19: NULL | Q19: NULL | R19: NULL | S19: 505050371 | T19: 54 | U19: Abidjan | V19: NULL | W19: NULL | X19: COCODY RIVIERA FAYA | Y19: NULL | Z19: 43479 | AA19: 1
A20: 1220743K | B20: 19 | C20: CISSE MOHMED SANASSY | D20: =VLOOKUP('[1]tblclients (1)'!A20,[1]Feuil1!$A$1:$G$203,4,0) -> DCK | E20: NULL | F20: NULL | G20: DCK-019 | H20: DCK-CGA2019-A028 | I20: NULL | J20: ENTREPRISE INDIVIDUELLE | K20: TEE | L20: NULL | M20: NULL | N20: NULL | O20: Riviera II | P20: NULL | Q20: NULL | R20: NULL | S20: 779941955 | T20: 54 | U20: Abidjan | V20: NULL | W20: NULL | X20: COCODY RIVIERA PALMERAIE | Y20: NULL | Z20: 43479 | AA20: 1
A21: 1807923J | B21: 20 | C21: EKYM SARL | D21: =VLOOKUP('[1]tblclients (1)'!A21,[1]Feuil1!$A$1:$G$203,4,0) -> DCK | E21: KOUADIO AHOU MICHAELLE | F21: GÃ©rante | G21: DCK-020 | H21: DCK-CGA2019-A006 | I21: CI-ABJ-2018-B-04208 | J21: SARL | K21: TEE | L21: Fournitures de bureaux, Restauration, BÃ¢timent | M21: EV | N21: 222 | O21: II Plateaux III | P21: SCE0203 | Q21: 1000000 | R21: N/D | S21: 102377494 | T21: 54 | U21: Abidjan | V21: 22 BP 799 ABIDJ | W21: N/D | X21: COCODY II PLATEAUX ANGRE | Y21: N/D | Z21: 43479 | AA21: 1
A22: 1648392M | B22: 21 | C22: KOUAME FIENI MYRIAME-CHRISTELLE | D22: =VLOOKUP('[1]tblclients (1)'!A22,[1]Feuil1!$A$1:$G$203,4,0) -> DCK | E22: NULL | F22: NULL | G22: DCK-021 | H22: DCK-CGA2019-A005 | I22: NULL | J22: ENTREPRISE INDIVIDUELLE | K22: TEE | L22: NULL | M22: NULL | N22: NULL | O22: Cocody | P22: NULL | Q22: NULL | R22: NULL | S22: 707063365 | T22: 54 | U22: Abidjan | V22: NULL | W22: NULL | X22: COCODY RIVIERA BONOUMIN | Y22: NULL | Z22: 43522 | AA22: 1
A23: 1212885P | B23: 22 | C23: YAO N'GUESSAN ADELE EPSE DJEDJE | D23: =VLOOKUP('[1]tblclients (1)'!A23,[1]Feuil1!$A$1:$G$203,4,0) -> DCK | E23: YOA N'GUESSAN ADELE EPSE DJEDJE | F23: Exploitante Individuelle | G23: DCK-022 | H23: DCK-CGA2019-A027 | I23: CI-ABJ-2012-A-1024 | J23: ENTREPRISE INDIVIDUELLE | K23: TEE | L23: ALIMENTATION GENERALE ET TRANSFERT D'ARGENT | M23: ABC | N23: 39 | O23: II Plateaux III | P23: SCE0101 | R23: N/D | S23: 505060740 | T23: 54 | U23: Abidjan | W23: N/D | X23: RIVIERA BONOUMIN | Y23: N/D | Z23: 43844 | AA23: 1
A24: 0714977C | B24: 23 | C24: YACE EMMANUELLE | D24: =VLOOKUP('[1]tblclients (1)'!A24,[1]Feuil1!$A$1:$G$203,4,0) -> DCK | E24: YACE EMMANUELLE | F24: Exploitante individuelle | G24: DCK-023 | H24: DCK-CGA2019-A014 | I24: CI-ABJ-2014-A-1249 | J24: ENTREPRISE INDIVIDUELLE | K24: TEE | L24: LOCATION DE SALLE ET TRAITEUR | M24: OZ | N24: 207 | O24: II Plateaux III | P24: SCE0708 | R24: N/D | S24: 707070392 | T24: 54 | U24: Abidjan | W24: N/D | X24: COCODY ANGRE 7E TRANCHE | Z24: 43844 | AA24: 1
A25: 1800364M | B25: 24 | C25: YAKIM DESIGN | D25: =VLOOKUP('[1]tblclients (1)'!A25,[1]Feuil1!$A$1:$G$203,4,0) -> DCK | E25: NULL | F25: NULL | G25: DCK-024 | H25: DCK-CGA2020-A104 | I25: NULL | J25: SARL | K25: TEE | L25: NULL | M25: NULL | N25: NULL | O25: II Plateaux I | P25: NULL | Q25: NULL | R25: NULL | S25: 2722413235 | T25: 54 | U25: Abidjan | V25: NULL | W25: NULL | X25: II PLATEAUX LES PERLES | Y25: NULL | Z25: 43845 | AA25: 1
A26: 1900445C | B26: 25 | C26: YAO N'DRI FRANCK AIME | D26: =VLOOKUP('[1]tblclients (1)'!A26,[1]Feuil1!$A$1:$G$203,4,0) -> DCK | E26: YAO N'DRI FRANCK AIME | F26: Exploitant Individuel | G26: DCK-025 | H26: DCK-CGA2020-A051 | J26: ENTREPRISE INDIVIDUELLE | K26: TEE | L26: PRESTATIONS MEDICALE | M26: ABH | N26: 10 | O26: II Plateaux III | P26: SCE1601 | R26: N/D | S26: 708112943 | T26: 54 | U26: Abidjan | W26: N/D | X26: COCODY BONOUMIN | Z26: 43847 | AA26: 1
A27: 1745011T | B27: 26 | C27: POHAN KEMOANFOUOGNON AUGUSTE | D27: =VLOOKUP('[1]tblclients (1)'!A27,[1]Feuil1!$A$1:$G$203,4,0) -> DCK | E27: POHAN KEMOANFOUOGON AUGUTE | F27: Exploitant individuel | G27: DCK-026 | H27: DCK-CGA2020-A088 | I27: CI-ABJ-2017-A-25544 | J27: ENTREPRISE INDIVIDUELLE | K27: TEE | L27: ASSISTANCE VOYAGE ET ETUDES, FORMATION, DIVERS | M27: AO | N27: 527 | O27: II Plateaux III | P27: SCE2399 | R27: N/D | S27: 778972145 | T27: 54 | U27: Abidjan | W27: N/D | X27: COCODY | Y27: N/D | Z27: 43858 | AA27: 1
A28: 2042595N | B28: 27 | C28: CNK INTERNATIONAL GROUP SARL | D28: =VLOOKUP('[1]tblclients (1)'!A28,[1]Feuil1!$A$1:$G$203,4,0) -> DCK | E28: NULL | F28: NULL | G28: DCK-027 | H28: DCK-CGA2020-A-111 | I28: NULL | J28: SARL | K28: TEE | L28: NULL | M28: NULL | N28: NULL | O28: Riviera I | P28: NULL | Q28: NULL | R28: NULL | S28: 779190538 | T28: 54 | U28: Abidjan | V28: NULL | W28: NULL | X28: COCODY RIVERA II CITE ESTUDIANTINE | Y28: NULL | Z28: 44111 | AA28: 1
A29: 1006441X | B29: 28 | C29: ETUDE DE MAITRE DIDIER DOUGOUE | D29: =VLOOKUP('[1]tblclients (1)'!A29,[1]Feuil1!$A$1:$G$203,4,0) -> DCK | E29: NULL | F29: NULL | G29: DCK-028 | H29: DCK-CGA2019-A120 | I29: NULL | J29: ENTREPRISE INDIVIDUELLE | K29: TEE | L29: NULL | M29: NULL | N29: NULL | O29: II Plateaux I | P29: NULL | Q29: NULL | R29: NULL | S29: 2722527459 | T29: 54 | U29: Abidjan | V29: NULL | W29: NULL | X29: COCODY ANGRE LES OSCARS | Y29: NULL | Z29: 44197 | AA29: 1
A30: 1351303J | B30: 29 | C30: NEYD DISTRIBUTION | D30: =VLOOKUP('[1]tblclients (1)'!A30,[1]Feuil1!$A$1:$G$203,4,0) -> DCK | E30: NULL | F30: NULL | G30: DCK-029 | H30: DCK-CGA2019-A118 | I30: NULL | J30: ENTREPRISE INDIVIDUELLE | K30: TEE | L30: NULL | M30: NULL | N30: NULL | O30: II Plateaux II | P30: NULL | Q30: NULL | R30: NULL | S30: 708302596 | T30: 54 | U30: Abidjan | V30: NULL | W30: NULL | X30: ANGRE 8E TRANCHE | Y30: NULL | Z30: 44197 | AA30: 1
A31: 0317890C | B31: 30 | C31: SCPA TAKORE, KONAN & ASSOCIES | D31: =VLOOKUP('[1]tblclients (1)'!A31,[1]Feuil1!$A$1:$G$203,4,0) -> DCK | E31: NULL | F31: NULL | G31: DCK-030 | H31: DCK-CGA2019-A119 | I31: NULL | J31: SOCIÃ‰TÃ‰ CIVILE | K31: TEE | L31: NULL | M31: NULL | N31: NULL | O31: II Plateaux II | P31: NULL | Q31: NULL | R31: NULL | S31: 2522014025 | T31: 54 | U31: Abidjan | V31: NULL | W31: NULL | X31: II PLATEAUX VALLON | Y31: NULL | Z31: 44197 | AA31: 1
A32: 1940880C | B32: 31 | C32: BOHIYA SERVICES SARL | D32: =VLOOKUP('[1]tblclients (1)'!A32,[1]Feuil1!$A$1:$G$203,4,0) -> DCK | E32: DANHI HENRY DELPHIN | F32: Co-gÃ©rant | G32: DCK-031 | H32: DCK-CGA2019-A117 | I32: CI-ABJ-2019-B-14607 | J32: SARL | K32: TEE | L32: VENTE DE TITRE DE TRANSPORT AERIEN ET TERRESTRE,MONETIQUE ET TRANSFERT D4ARGENT RAPIDE NATIONAUX ET INTERNATIONAUX | M32: OZ | N32: 281 | O32: II Plateaux III | P32: SCE0313 | Q32: 1000000 | R32: N/D | S32: 2722594787 | T32: 54 | U32: Abidjan | W32: BS SARL | X32: COCODY ANGRE 7E TRANCHE | Y32: N/D | Z32: 44197 | AA32: 1
A33: 2035080J | B33: 32 | C33: DEBOLYINSTRUMENTS SARL | D33: =VLOOKUP('[1]tblclients (1)'!A33,[1]Feuil1!$A$1:$G$203,4,0) -> DCK | E33: NULL | F33: NULL | G33: DCK-032 | H33: DCK-CGA2020-A115 | I33: NULL | J33: SARL | K33: TEE | L33: NULL | M33: NULL | N33: NULL | O33: Riviera I | P33: NULL | Q33: NULL | R33: NULL | S33: 707053694 | T33: 54 | U33: Abidjan | V33: NULL | W33: NULL | X33: RIVIERA 3 MOSQUEE | Y33: NULL | Z33: 44197 | AA33: 1
A34: 1224798B | B34: 33 | C34: KADIO-MOROKRO MAUD AICHA (FOR MEN) | D34: =VLOOKUP('[1]tblclients (1)'!A34,[1]Feuil1!$A$1:$G$203,4,0) -> DCK | E34: NULL | F34: NULL | G34: DCK-033 | H34: DCK-CGA-2021-Q154 | I34: NULL | J34: ENTREPRISE INDIVIDUELLE | K34: TEE | L34: NULL | M34: NULL | N34: NULL | O34: II Plateaux II | P34: NULL | Q34: NULL | R34: NULL | S34: 749820808 | T34: 54 | U34: Abidjan | V34: NULL | W34: NULL | X34: COCODY II PLATEAUX VALLON | Y34: NULL | Z34: 44224 | AA34: 1
A35: 1927845K | B35: 34 | C35: PHILIPPE INES GROUP | D35: =VLOOKUP('[1]tblclients (1)'!A35,[1]Feuil1!$A$1:$G$203,4,0) -> DCK | E35: NULL | F35: NULL | G35: DCK-034 | H35: DCK-CGA-2021-Q174 | I35: NULL | J35: SARL | K35: TEE | L35: NULL | M35: NULL | N35: NULL | O35: II Plateaux II | P35: NULL | Q35: NULL | R35: NULL | S35: 77767968 | T35: 54 | U35: Abidjan | V35: NULL | W35: NULL | X35: II PLATEAUX | Y35: NULL | Z35: 44224 | AA35: 1
A36: 1947542X | B36: 35 | C36: OREMUS SARLU | D36: =VLOOKUP('[1]tblclients (1)'!A36,[1]Feuil1!$A$1:$G$203,4,0) -> DCK | E36: YEBOUE EPSE BOUAH ADJOUA IRENE | F36: GÃ©rante | G36: DCK-035 | H36: DCK-CGA2024-A050 | I36: CI-ABJ-2019-B-17445 | J36: SARL | K36: TEE | L36: LOCATIONS MATERIELS ,EVEMENTIELS,LOCATION VEHICULE | M36: N/D | N36: N/D | O36: II Pateaux II | P36: SCC0701 | Q36: 5000000 | R36: N/D | S36: 707830824 | T36: 54 | U36: Abidjan | V36: 08 BP 21115 ABI | W36: N/D | X36: COCODY II PLATEAUX VALLON | Y36: N/D | Z36: 44224 | AA36: 1
A37: 2110646D | B37: 36 | C37: IVOIR QUALITE ET SERVICES | D37: =VLOOKUP('[1]tblclients (1)'!A37,[1]Feuil1!$A$1:$G$203,4,0) -> DCK | E37: NULL | F37: NULL | G37: DCK-036 | H37: DCK-CGA-2021-Q172 | I37: NULL | J37: SARL | K37: RME | L37: NULL | M37: NULL | N37: NULL | O37: II Plateaux I | P37: NULL | Q37: NULL | R37: NULL | S37: 2722427504 | T37: 54 | U37: Abidjan | V37: NULL | W37: NULL | X37: COCODY-ANGRÃ‰-CITÃ‰ BEL HORIZON | Y37: NULL | Z37: 44264 | AA37: 1
A38: 2196217J | B38: 37 | C38: SANTE & SECURITE AU TRAVAIL | D38: =VLOOKUP('[1]tblclients (1)'!A38,[1]Feuil1!$A$1:$G$203,4,0) -> DCK | E38: NULL | F38: NULL | G38: DCK-037 | H38: DCK-CGA-2022-J002 | I38: NULL | J38: SARL | K38: TEE | L38: NULL | M38: NULL | N38: NULL | O38: Riviera I | P38: NULL | Q38: NULL | R38: NULL | S38: 566284952 | T38: 54 | U38: Abidjan | V38: NULL | W38: NULL | X38: COCODY RIVIERA GOLF ANONO | Y38: NULL | Z38: 44564 | AA38: 1
A39: 1865233X | B39: 38 | C39: YAPO YAPO GHISLAIN CYRILLE | D39: =VLOOKUP('[1]tblclients (1)'!A39,[1]Feuil1!$A$1:$G$203,4,0) -> DCK | E39: NULL | F39: NULL | G39: DCK-038 | H39: DCK-CGA-2022-J004 | I39: NULL | J39: ENTREPRISE INDIVIDUELLE | K39: TEE | L39: NULL | M39: NULL | N39: NULL | O39: Riviera I | P39: NULL | Q39: NULL | R39: NULL | S39: 778120796 | T39: 54 | U39: Abidjan | V39: NULL | W39: NULL | X39: COCODY RIVIERA II | Y39: NULL | Z39: 44574 | AA39: 1
A40: 2114065J | B40: 39 | C40: POSY SECURITY AND SERVICES | D40: =VLOOKUP('[1]tblclients (1)'!A40,[1]Feuil1!$A$1:$G$203,4,0) -> DCK | E40: NULL | F40: NULL | G40: DCK-039 | H40: DCK-CGA-2022-J011 | I40: NULL | J40: SARL | K40: TEE | L40: NULL | M40: NULL | N40: NULL | O40: II Plateaux I | P40: NULL | Q40: NULL | R40: NULL | S40: 103041792 | T40: 54 | U40: Abidjan | V40: NULL | W40: NULL | X40: COCODY ANGRE | Y40: NULL | Z40: 44588 | AA40: 1
...

Sheet Feuil1
A1: numcc | B1: userid | C1: company | D1: vat | E1: identification | F1: fonction | G1: numcga | H1: numadh | I1: numrccm | J1: formjurid | K1: regime | L1: acti_prin | M1: section | N1: parcelle | O1: imp_centre | P1: codeacti | Q1: montcapit | R1: emailetprse | S1: phonenumber | T1: country | U1: city | V1: zip | W1: state | X1: address | Y1: website | Z1: datecreated | AA1: active | AB1: leadid | AC1: billing_street | AD1: billing_city | AE1: billing_state | AF1: billing_zip | AG1: billing_country | AH1: shipping_street | AI1: shipping_city | AJ1: shipping_state | AK1: shipping_zip | AL1: shipping_country | AM1: longitude | AN1: latitude | AO1: default_language | AP1: default_currency | AQ1: show_primary_contact | AR1: stripe_id | AS1: registration_confirmed | AT1: addedfrom
A2: 4105181N | B2: 1 | C2: HONDE REINE BELLE | D2: NULL | E2: NULL | F2: NULL | G2: DCK-001 | H2: DCK-CGA2019-A026 | I2: NULL | J2: ENTREPRISE INDIVIDUELLE | K2: TEE | L2: NULL | M2: NULL | N2: NULL | O2: II Plateaux II | P2: NULL | Q2: NULL | R2: NULL | S2: 707059199 | T2: 54 | U2: Abidjan | V2: NULL | W2: NULL | X2: COCODY II PLATEAUX VALLONS | Y2: NULL | Z2: 43466 | AA2: 1 | AB2: NULL | AC2: NULL | AD2: NULL | AE2: NULL | AF2: NULL | AG2: NULL | AH2: NULL | AI2: NULL | AJ2: NULL | AK2: NULL | AL2: NULL | AM2: NULL | AN2: NULL | AO2: NULL | AP2: 3 | AQ2: 1 | AR2: NULL | AS2: 1 | AT2: 1
A3: 1526919K | B3: 2 | C3: GOLY ADJOUA EDITH ESTELLE | D3: NULL | E3: GOLY ADJOUA EDITH ESTELLE | F3: Exploitante individuelle | G3: DCK-002 | H3: DCK-CGA2019-A013 | I3: CI-ABJ-2015-A-3981 | J3: ENTREPRISE INDIVIDUELLE | K3: TEE | L3: Fourniture de bureau | M3: EV | N3: 541 | O3: II Plateaux III | P3: CCE1501 | R3: N/D | S3: 758840340 | T3: 54 | U3: Abidjan | V3: 09 BP 1976 ABID | W3: N/D | X3: COCODY RIVERA BONOUMIN | Y3: N/D | Z3: 43466 | AA3: 1 | AB3: NULL | AC3: NULL | AG3: 0 | AL3: 0 | AM3: NULL | AN3: NULL | AO3: NULL | AP3: 0 | AQ3: 1 | AR3: NULL | AS3: 1 | AT3: 1
A4: 1435907M | B4: 3 | C4: ETTE DJEKET CORINE EPSE AVOAKA | D4: NULL | E4: NULL | F4: NULL | G4: DCK-003 | H4: DCK-CGA2020-A050 | I4: NULL | J4: ENTREPRISE INDIVIDUELLE | K4: TEE | L4: NULL | M4: NULL | N4: NULL | O4: Cocody | P4: NULL | Q4: NULL | R4: NULL | S4: 707114141 | T4: 54 | U4: Abidjan | V4: NULL | W4: NULL | X4: COCODY BLOCKAUSS | Y4: NULL | Z4: 43471 | AA4: 1 | AB4: NULL | AC4: NULL | AD4: NULL | AE4: NULL | AF4: NULL | AG4: NULL | AH4: NULL | AI4: NULL | AJ4: NULL | AK4: NULL | AL4: NULL | AM4: NULL | AN4: NULL | AO4: NULL | AP4: 3 | AQ4: 1 | AR4: NULL | AS4: 1 | AT4: 1
A5: 0323332D | B5: 4 | C5: KONATE Harouna | D5: NULL | E5: NULL | F5: NULL | G5: DCK-004 | H5: DCK-CGA2019-A039 | I5: NULL | J5: ENTREPRISE INDIVIDUELLE | K5: TEE | L5: NULL | M5: NULL | N5: NULL | O5: Cocody | P5: NULL | Q5: NULL | R5: NULL | S5: 707941178 | T5: 54 | U5: Abidjan | V5: NULL | W5: NULL | X5: COCODY SAINT JEAN | Y5: NULL | Z5: 43479 | AA5: 1 | AB5: NULL | AC5: NULL | AD5: NULL | AE5: NULL | AF5: NULL | AG5: NULL | AH5: NULL | AI5: NULL | AJ5: NULL | AK5: NULL | AL5: NULL | AM5: NULL | AN5: NULL | AO5: NULL | AP5: 3 | AQ5: 1 | AR5: NULL | AS5: 1 | AT5: 1
A6: 1507261D | B6: 5 | C6: ZANGRE HAROUNA | D6: NULL | E6: NULL | F6: NULL | G6: DCK-005 | H6: DCK-CGA2019-A024 | I6: NULL | J6: ENTREPRISE INDIVIDUELLE | K6: TEE | L6: NULL | M6: NULL | N6: NULL | O6: Cocody | P6: NULL | Q6: NULL | R6: NULL | S6: 505843545 | T6: 54 | U6: Abidjan | V6: NULL | W6: NULL | X6: COCODY SAINT JEAN | Y6: NULL | Z6: 43479 | AA6: 1 | AB6: NULL | AC6: NULL | AD6: NULL | AE6: NULL | AF6: NULL | AG6: NULL | AH6: NULL | AI6: NULL | AJ6: NULL | AK6: NULL | AL6: NULL | AM6: NULL | AN6: NULL | AO6: NULL | AP6: 3 | AQ6: 1 | AR6: NULL | AS6: 1 | AT6: 1
A7: 1414480Q | B7: 6 | C7: OUEDRAOGO YOUSSOUF | D7: NULL | E7: NULL | F7: NULL | G7: DCK-006 | H7: DCK-CGA2019-A023 | I7: NULL | J7: ENTREPRISE INDIVIDUELLE | K7: TEE | L7: NULL | M7: NULL | N7: NULL | O7: Cocody | P7: NULL | Q7: NULL | R7: NULL | S7: 707582591 | T7: 54 | U7: Abidjan | V7: NULL | W7: NULL | X7: COCODY SAINT JEAN | Y7: NULL | Z7: 43479 | AA7: 1 | AB7: NULL | AC7: NULL | AD7: NULL | AE7: NULL | AF7: NULL | AG7: NULL | AH7: NULL | AI7: NULL | AJ7: NULL | AK7: NULL | AL7: NULL | AM7: NULL | AN7: NULL | AO7: NULL | AP7: 3 | AQ7: 1 | AR7: NULL | AS7: 1 | AT7: 1
A8: 1827528R | B8: 7 | C8: YAGUERA & COMPAGNIE | D8: NULL | E8: NULL | F8: NULL | G8: DCK-007 | H8: DCK-CGA2019-A007 | I8: NULL | J8: SARL | K8: TEE | L8: NULL | M8: NULL | N8: NULL | O8: II Plateaux I | P8: NULL | Q8: NULL | R8: NULL | S8: 789844008 | T8: 54 | U8: Abidjan | V8: NULL | W8: NULL | X8: COCODY ANGRE 7E TRANCHE | Y8: NULL | Z8: 43479 | AA8: 1 | AB8: NULL | AC8: NULL | AD8: NULL | AE8: NULL | AF8: NULL | AG8: NULL | AH8: NULL | AI8: NULL | AJ8: NULL | AK8: NULL | AL8: NULL | AM8: NULL | AN8: NULL | AO8: NULL | AP8: 3 | AQ8: 1 | AR8: NULL | AS8: 1 | AT8: 1
A9: 1619903H | B9: 8 | C9: NEDJMA SARLU | D9: NULL | E9: NULL | F9: NULL | G9: DCK-008 | H9: DCK-CGA2019-A029 | I9: NULL | J9: SARL | K9: TEE | L9: NULL | M9: NULL | N9: NULL | O9: II Plateaux I | P9: NULL | Q9: NULL | R9: NULL | S9: 707070102 | T9: 54 | U9: Abidjan | V9: NULL | W9: NULL | X9: COCODY RIVIERA BONOUMIN | Y9: NULL | Z9: 43479 | AA9: 1 | AB9: NULL | AC9: NULL | AD9: NULL | AE9: NULL | AF9: NULL | AG9: NULL | AH9: NULL | AI9: NULL | AJ9: NULL | AK9: NULL | AL9: NULL | AM9: NULL | AN9: NULL | AO9: NULL | AP9: 3 | AQ9: 1 | AR9: NULL | AS9: 1 | AT9: 1
